Workbook

Sheet README
A1: LIFE INSURANCE PRICING & VALUATION MODEL
A3: Portfolio Project | B3: Life Insurance Pricing & Valuation Model
A4: Tools | B4: Microsoft Excel (actuarial modelling, formulas, data analysis)
A5: Scope | B5: Whole life, endowment and term assurance policies with non-participating and participating benefits.
A6: Objective | B6: Build an Excel-based actuarial model to calculate net premium rates and prospective policy reserves using the DGI mortality table and commutation functions.
A7: Key methods | B7: Actuarial present values, net premium calculation, participating bonus analysis, prospective reserves, and portfolio summaries.
A8: Dataset | B8: 109 policyholder records generated for actuarial modelling and demonstration.
A9: Mortality basis | B9: DGI96 mortality table with qx and commutation functions Dx, Nx, Sx, Cx, Mx and Rx.
A10: Policy types | B10: Whole Life (WNP/WPS/WPC), Endowment (ENP/EPS/EPC), Term (TNP/TPS/TPC).
A11: Portfolio outputs | B11: Pricing Analysis, Reserve Analysis, Dashboard and policy-level calculations.
A12: Note | B12: This is a portfolio adaptation of an actuarial modelling exercise. Values are based on the model assumptions and mortality basis contained in the workbook.
A13: Author | B13: Muhammad Aiman bin Azaman
A14: Focus | B14: Actuarial Science | Insurance Data Analytics

Sheet Dashboard
A1: LIFE INSURANCE PRICING & VALUATION DASHBOARD
A3: Policyholders | D3: Policy Types | G3: Total Sum Assured
A4: =COUNTA('Policyholder Data'!$A$2:$A$110) -> 109 | D4: =COUNTA('Pricing Analysis'!$A$4:$A$12) -> 9 | G4: =SUM('Policyholder Data'!$G$2:$G$110) -> 11745000
A7: Average Net Premium Rate | D7: Total Reserves | G7: Participating Policies
A8: =IFERROR(AVERAGE('Policyholder Data'!$O$2:$O$110),0) -> 0.064527775 | D8: =SUM('Policyholder Data'!$X$2:$X$110) -> 2978927 | G8: =COUNTIF('Policyholder Data'!$I$2:$I$110,"<>None") -> 69
A11: Policy Type | B11: Policyholders | C11: Avg Net Premium Rate | D11: Average Reserve
A12: WNP | B12: ='Pricing Analysis'!B4 -> 14 | C12: ='Pricing Analysis'!D4 -> 0.02868487 | D12: ='Reserve Analysis'!D4 -> 9476.0929
A13: WPS | B13: ='Pricing Analysis'!B5 -> 11 | C13: ='Pricing Analysis'!D5 -> 0.028883607 | D13: ='Reserve Analysis'!D5 -> 22609.772
A14: WPC | B14: ='Pricing Analysis'!B6 -> 13 | C14: ='Pricing Analysis'!D6 -> 0.041336133 | D14: ='Reserve Analysis'!D6 -> 25541.222
A15: ENP | B15: ='Pricing Analysis'!B7 -> 14 | C15: ='Pricing Analysis'!D7 -> 0.13480351 | D15: ='Reserve Analysis'!D7 -> 1569.7565
A16: EPS | B16: ='Pricing Analysis'!B8 -> 18 | C16: ='Pricing Analysis'!D8 -> 0.12334219 | D16: ='Reserve Analysis'!D8 -> 5201.1919
A17: EPC | B17: ='Pricing Analysis'!B9 -> 11 | C17: ='Pricing Analysis'!D9 -> 0.12073547 | D17: ='Reserve Analysis'!D9 -> 3985.511
A18: TNP | B18: ='Pricing Analysis'!B10 -> 12 | C18: ='Pricing Analysis'!D10 -> 0.015643897 | D18: ='Reserve Analysis'!D10 -> 75939.434
A19: TPS | B19: ='Pricing Analysis'!B11 -> 6 | C19: ='Pricing Analysis'!D11 -> 0.015530926 | D19: ='Reserve Analysis'!D11 -> 90357.027
A20: TPC | B20: ='Pricing Analysis'!B12 -> 10 | C20: ='Pricing Analysis'!D12 -> 0.0060438869 | D20: ='Reserve Analysis'!D12 -> 65266.425

Sheet Pricing Analysis
A1: PRICING ANALYSIS
A3: Policy Type | B3: Policyholders | C3: Total Sum Assured | D3: Average Net Premium Rate | E3: Minimum Net Premium Rate | F3: Maximum Net Premium Rate
A4: WNP | B4: =COUNTIF('Policyholder Data'!$E$2:$E$110,A4) -> 14 | C4: =SUMIF('Policyholder Data'!$E$2:$E$110,A4,'Policyholder Data'!$G$2:$G$110) -> 1675000 | D4: =IFERROR(AVERAGEIF('Policyholder Data'!$E$2:$E$110,A4,'Policyholder Data'!$O$2:$O$110),0) -> 0.02868487 | E4: 0.010016067 | F4: 0.065438245
A5: WPS | B5: =COUNTIF('Policyholder Data'!$E$2:$E$110,A5) -> 11 | C5: =SUMIF('Policyholder Data'!$E$2:$E$110,A5,'Policyholder Data'!$G$2:$G$110) -> 1140000 | D5: =IFERROR(AVERAGEIF('Policyholder Data'!$E$2:$E$110,A5,'Policyholder Data'!$O$2:$O$110),0) -> 0.028883607 | E5: 0.011258703 | F5: 0.072152307
A6: WPC | B6: =COUNTIF('Policyholder Data'!$E$2:$E$110,A6) -> 13 | C6: =SUMIF('Policyholder Data'!$E$2:$E$110,A6,'Policyholder Data'!$G$2:$G$110) -> 1365000 | D6: =IFERROR(AVERAGEIF('Policyholder Data'!$E$2:$E$110,A6,'Policyholder Data'!$O$2:$O$110),0) -> 0.041336133 | E6: 0.010603014 | F6: 0.084427152
A7: ENP | B7: =COUNTIF('Policyholder Data'!$E$2:$E$110,A7) -> 14 | C7: =SUMIF('Policyholder Data'!$E$2:$E$110,A7,'Policyholder Data'!$G$2:$G$110) -> 1445000 | D7: =IFERROR(AVERAGEIF('Policyholder Data'!$E$2:$E$110,A7,'Policyholder Data'!$O$2:$O$110),0) -> 0.13480351 | E7: 0.029529145 | F7: 0.28566232
A8: EPS | B8: =COUNTIF('Policyholder Data'!$E$2:$E$110,A8) -> 18 | C8: =SUMIF('Policyholder Data'!$E$2:$E$110,A8,'Policyholder Data'!$G$2:$G$110) -> 2025000 | D8: =IFERROR(AVERAGEIF('Policyholder Data'!$E$2:$E$110,A8,'Policyholder Data'!$O$2:$O$110),0) -> 0.12334219 | E8: 0.02798709 | F8: 0.28943409
A9: EPC | B9: =COUNTIF('Policyholder Data'!$E$2:$E$110,A9) -> 11 | C9: =SUMIF('Policyholder Data'!$E$2:$E$110,A9,'Policyholder Data'!$G$2:$G$110) -> 1175000 | D9: =IFERROR(AVERAGEIF('Policyholder Data'!$E$2:$E$110,A9,'Policyholder Data'!$O$2:$O$110),0) -> 0.12073547 | E9: 0.027898121 | F9: 0.28624452
A10: TNP | B10: =COUNTIF('Policyholder Data'!$E$2:$E$110,A10) -> 12 | C10: =SUMIF('Policyholder Data'!$E$2:$E$110,A10,'Policyholder Data'!$G$2:$G$110) -> 1350000 | D10: =IFERROR(AVERAGEIF('Policyholder Data'!$E$2:$E$110,A10,'Policyholder Data'!$O$2:$O$110),0) -> 0.015643897 | E10: 0.0022365457 | F10: 0.09562497
A11: TPS | B11: =COUNTIF('Policyholder Data'!$E$2:$E$110,A11) -> 6 | C11: =SUMIF('Policyholder Data'!$E$2:$E$110,A11,'Policyholder Data'!$G$2:$G$110) -> 680000 | D11: =IFERROR(AVERAGEIF('Policyholder Data'!$E$2:$E$110,A11,'Policyholder Data'!$O$2:$O$110),0) -> 0.015530926 | E11: 0.002368789 | F11: 0.036242431
A12: TPC | B12: =COUNTIF('Policyholder Data'!$E$2:$E$110,A12) -> 10 | C12: =SUMIF('Policyholder Data'!$E$2:$E$110,A12,'Policyholder Data'!$G$2:$G$110) -> 890000 | D12: =IFERROR(AVERAGEIF('Policyholder Data'!$E$2:$E$110,A12,'Policyholder Data'!$O$2:$O$110),0) -> 0.0060438869 | E12: 0.0025886871 | F12: 0.017973683

Sheet Reserve Analysis
A1: RESERVE ANALYSIS
A3: Policy Type | B3: Policyholders | C3: Total Reserve | D3: Average Reserve | E3: Maximum Reserve
A4: WNP | B4: =COUNTIF('Policyholder Data'!$E$2:$E$110,A4) -> 14 | C4: =SUMIF('Policyholder Data'!$E$2:$E$110,A4,'Policyholder Data'!$X$2:$X$110) -> 132665.3 | D4: =IFERROR(AVERAGEIF('Policyholder Data'!$E$2:$E$110,A4,'Policyholder Data'!$X$2:$X$110),0) -> 9476.0929 | E4: 25291.016
A5: WPS | B5: =COUNTIF('Policyholder Data'!$E$2:$E$110,A5) -> 11 | C5: =SUMIF('Policyholder Data'!$E$2:$E$110,A5,'Policyholder Data'!$X$2:$X$110) -> 248707.49 | D5: =IFERROR(AVERAGEIF('Policyholder Data'!$E$2:$E$110,A5,'Policyholder Data'!$X$2:$X$110),0) -> 22609.772 | E5: 73013.599
A6: WPC | B6: =COUNTIF('Policyholder Data'!$E$2:$E$110,A6) -> 13 | C6: =SUMIF('Policyholder Data'!$E$2:$E$110,A6,'Policyholder Data'!$X$2:$X$110) -> 332035.89 | D6: =IFERROR(AVERAGEIF('Policyholder Data'!$E$2:$E$110,A6,'Policyholder Data'!$X$2:$X$110),0) -> 25541.222 | E6: 49289.406
A7: ENP | B7: =COUNTIF('Policyholder Data'!$E$2:$E$110,A7) -> 14 | C7: =SUMIF('Policyholder Data'!$E$2:$E$110,A7,'Policyholder Data'!$X$2:$X$110) -> 21976.591 | D7: =IFERROR(AVERAGEIF('Policyholder Data'!$E$2:$E$110,A7,'Policyholder Data'!$X$2:$X$110),0) -> 1569.7565 | E7: 5563.2243
A8: EPS | B8: =COUNTIF('Policyholder Data'!$E$2:$E$110,A8) -> 18 | C8: =SUMIF('Policyholder Data'!$E$2:$E$110,A8,'Policyholder Data'!$X$2:$X$110) -> 93621.454 | D8: =IFERROR(AVERAGEIF('Policyholder Data'!$E$2:$E$110,A8,'Policyholder Data'!$X$2:$X$110),0) -> 5201.1919 | E8: 26818.276
A9: EPC | B9: =COUNTIF('Policyholder Data'!$E$2:$E$110,A9) -> 11 | C9: =SUMIF('Policyholder Data'!$E$2:$E$110,A9,'Policyholder Data'!$X$2:$X$110) -> 43840.621 | D9: =IFERROR(AVERAGEIF('Policyholder Data'!$E$2:$E$110,A9,'Policyholder Data'!$X$2:$X$110),0) -> 3985.511 | E9: 15658.233
A10: TNP | B10: =COUNTIF('Policyholder Data'!$E$2:$E$110,A10) -> 12 | C10: =SUMIF('Policyholder Data'!$E$2:$E$110,A10,'Policyholder Data'!$X$2:$X$110) -> 911273.2 | D10: =IFERROR(AVERAGEIF('Policyholder Data'!$E$2:$E$110,A10,'Policyholder Data'!$X$2:$X$110),0) -> 75939.434 | E10: 144440.82
A11: TPS | B11: =COUNTIF('Policyholder Data'!$E$2:$E$110,A11) -> 6 | C11: =SUMIF('Policyholder Data'!$E$2:$E$110,A11,'Policyholder Data'!$X$2:$X$110) -> 542142.16 | D11: =IFERROR(AVERAGEIF('Policyholder Data'!$E$2:$E$110,A11,'Policyholder Data'!$X$2:$X$110),0) -> 90357.027 | E11: 131700.36
A12: TPC | B12: =COUNTIF('Policyholder Data'!$E$2:$E$110,A12) -> 10 | C12: =SUMIF('Policyholder Data'!$E$2:$E$110,A12,'Policyholder Data'!$X$2:$X$110) -> 652664.25 | D12: =IFERROR(AVERAGEIF('Policyholder Data'!$E$2:$E$110,A12,'Policyholder Data'!$X$2:$X$110),0) -> 65266.425 | E12: 164035.96

Sheet Sensitivity
A1: SENSITIVITY ANALYSIS
A3: Selected Policy Type | B3: ENP
A4: Base Average Net Premium Rate | B4: =IFERROR(INDEX('Pricing Analysis'!$D$4:$D$12,MATCH(B3,'Pricing Analysis'!$A$4:$A$12,0)),0) -> 0.13480351
A6: Scenario | B6: Rate Multiplier | C6: Adjusted Premium Rate
A7: Base | B7: 1 | C7: =B4*B7 -> 0.13480351
A8: −10% | B8: 0.9 | C8: =B4*B8 -> 0.12132316
A9: −5% | B9: 0.95 | C9: =B4*B9 -> 0.12806333
A10: +5% | B10: 1.05 | C10: =B4*B10 -> 0.14154368
A11: +10% | B11: 1.1 | C11: =B4*B11 -> 0.14828386

Sheet Data Generator
A1: No. | B1: Name | C1: Gender | D1: Age at Issue, x | E1: Policy | F1: Policy Term, n | G1: Sum Assured | H1: Premium Term, h | I1: Type of Bonus | J1: Bonus % | K1: Time Since Inception, t
A2: 1 | B2: {=IF(C2="M",INDEX('Random Lists'!$A$2:$A$56,COUNTIF($C$2:C2,"M")),INDEX('Random Lists'!$B$2:$B$55,COUNTIF($C$2:C2,"F")))} -> NURUL HUSNA BINTI SHAH | C2: =IF(RAND()<55/109,"M","F") -> F | D2: =RANDBETWEEN(18,60) -> 47 | E2: =CHOOSE(RANDBETWEEN(1,9),"WNP","WPS","WPC","ENP","EPS","EPC","TNP","TPS","TPC") -> ENP | F2: =IF(LEFT(E2,1)="W","N/A",CHOOSE(RANDBETWEEN(1,5),5,10,15,20,25)) -> 20 | G2: =CHOOSE(RANDBETWEEN(1,12),50000,55000,60000,75000,80000,100000,120000,125000,150000,175000,180000,200000) -> 150000 | H2: =IF(LEFT(E2,1)="W",CHOOSE(RANDBETWEEN(1,5),5,10,15,20,25),RANDBETWEEN(1,F2/5)*5) -> 15 | I2: =IF(RIGHT(E2,2)="NP","None",IF(RIGHT(E2,1)="S","SRB","CRB")) -> None | J2: =IF(I2="None",0%,5%) -> 0 | K2: =IF(LEFT(E2,1)="W",RANDBETWEEN(1,10),RANDBETWEEN(1,MIN(10,F2))) -> 10
A3: 2 | B3: {=IF(C3="M",INDEX('Random Lists'!$A$2:$A$56,COUNTIF($C$2:C3,"M")),INDEX('Random Lists'!$B$2:$B$55,COUNTIF($C$2:C3,"F")))} -> NUR SYAZWANI BINTI SALLEH | C3: =IF(COUNTIF($C$2:C2,"M")>=55,"F",IF(COUNTIF($C$2:C2,"F")>=54,"M",IF(RAND()<55/109,"M","F"))) -> F | D3: =RANDBETWEEN(18,60) -> 42 | E3: =CHOOSE(RANDBETWEEN(1,9),"WNP","WPS","WPC","ENP","EPS","EPC","TNP","TPS","TPC") -> WNP | F3: =IF(LEFT(E3,1)="W","N/A",CHOOSE(RANDBETWEEN(1,5),5,10,15,20,25)) -> N/A | G3: =CHOOSE(RANDBETWEEN(1,11),50000,60000,75000,80000,100000,120000,125000,150000,175000,180000,200000) -> 75000 | H3: =IF(LEFT(E3,1)="W",CHOOSE(RANDBETWEEN(1,5),5,10,15,20,25),RANDBETWEEN(1,F3/5)*5) -> 10 | I3: =IF(RIGHT(E3,2)="NP","None",IF(RIGHT(E3,1)="S","SRB","CRB")) -> None | J3: =IF(I3="None",0%,5%) -> 0 | K3: =IF(LEFT(E3,1)="W",RANDBETWEEN(1,10),RANDBETWEEN(1,MIN(10,F3))) -> 9
A4: 3 | B4: {=IF(C4="M",INDEX('Random Lists'!$A$2:$A$56,COUNTIF($C$2:C4,"M")),INDEX('Random Lists'!$B$2:$B$55,COUNTIF($C$2:C4,"F")))} -> MUHAMMAD HAZIQ BIN SHAH | C4: =IF(COUNTIF($C$2:C3,"M")>=55,"F",IF(COUNTIF($C$2:C3,"F")>=54,"M",IF(RAND()<55/109,"M","F"))) -> M | D4: =RANDBETWEEN(18,60) -> 51 | E4: =CHOOSE(RANDBETWEEN(1,9),"WNP","WPS","WPC","ENP","EPS","EPC","TNP","TPS","TPC") -> EPS | F4: =IF(LEFT(E4,1)="W","N/A",CHOOSE(RANDBETWEEN(1,5),5,10,15,20,25)) -> 25 | G4: =CHOOSE(RANDBETWEEN(1,11),50000,60000,75000,80000,100000,120000,125000,150000,175000,180000,200000) -> 175000 | H4: =IF(LEFT(E4,1)="W",CHOOSE(RANDBETWEEN(1,5),5,10,15,20,25),RANDBETWEEN(1,F4/5)*5) -> 15 | I4: =IF(RIGHT(E4,2)="NP","None",IF(RIGHT(E4,1)="S","SRB","CRB")) -> SRB | J4: =IF(I4="None",0%,5%) -> 0.05 | K4: =IF(LEFT(E4,1)="W",RANDBETWEEN(1,10),RANDBETWEEN(1,MIN(10,F4))) -> 5
A5: 4 | B5: {=IF(C5="M",INDEX('Random Lists'!$A$2:$A$56,COUNTIF($C$2:C5,"M")),INDEX('Random Lists'!$B$2:$B$55,COUNTIF($C$2:C5,"F")))} -> NUR SHAFIQAH BINTI MAHADI | C5: =IF(COUNTIF($C$2:C4,"M")>=55,"F",IF(COUNTIF($C$2:C4,"F")>=54,"M",IF(RAND()<55/109,"M","F"))) -> F | D5: =RANDBETWEEN(18,60) -> 42 | E5: =CHOOSE(RANDBETWEEN(1,9),"WNP","WPS","WPC","ENP","EPS","EPC","TNP","TPS","TPC") -> TPC | F5: =IF(LEFT(E5,1)="W","N/A",CHOOSE(RANDBETWEEN(1,5),5,10,15,20,25)) -> 5 | G5: =CHOOSE(RANDBETWEEN(1,11),50000,60000,75000,80000,100000,120000,125000,150000,175000,180000,200000) -> 50000 | H5: =IF(LEFT(E5,1)="W",CHOOSE(RANDBETWEEN(1,5),5,10,15,20,25),RANDBETWEEN(1,F5/5)*5) -> 5 | I5: =IF(RIGHT(E5,2)="NP","None",IF(RIGHT(E5,1)="S","SRB","CRB")) -> CRB | J5: =IF(I5="None",0%,5%) -> 0.05 | K5: =IF(LEFT(E5,1)="W",RANDBETWEEN(1,10),RANDBETWEEN(1,MIN(10,F5))) -> 1
A6: 5 | B6: {=IF(C6="M",INDEX('Random Lists'!$A$2:$A$56,COUNTIF($C$2:C6,"M")),INDEX('Random Lists'!$B$2:$B$55,COUNTIF($C$2:C6,"F")))} -> MUHAMMAD HAZWAN BIN RAMLI | C6: =IF(COUNTIF($C$2:C5,"M")>=55,"F",IF(COUNTIF($C$2:C5,"F")>=54,"M",IF(RAND()<55/109,"M","F"))) -> M | D6: =RANDBETWEEN(18,60) -> 21 | E6: =CHOOSE(RANDBETWEEN(1,9),"WNP","WPS","WPC","ENP","EPS","EPC","TNP","TPS","TPC") -> TPC | F6: =IF(LEFT(E6,1)="W","N/A",CHOOSE(RANDBETWEEN(1,5),5,10,15,20,25)) -> 20 | G6: =CHOOSE(RANDBETWEEN(1,11),50000,60000,75000,80000,100000,120000,125000,150000,175000,180000,200000) -> 100000 | H6: =IF(LEFT(E6,1)="W",CHOOSE(RANDBETWEEN(1,5),5,10,15,20,25),RANDBETWEEN(1,F6/5)*5) -> 5 | I6: =IF(RIGHT(E6,2)="NP","None",IF(RIGHT(E6,1)="S","SRB","CRB")) -> CRB | J6: =IF(I6="None",0%,5%) -> 0.05 | K6: =IF(LEFT(E6,1)="W",RANDBETWEEN(1,10),RANDBETWEEN(1,MIN(10,F6))) -> 2
A7: 6 | B7: {=IF(C7="M",INDEX('Random Lists'!$A$2:$A$56,COUNTIF($C$2:C7,"M")),INDEX('Random Lists'!$B$2:$B$55,COUNTIF($C$2:C7,"F")))} -> MUHAMMAD IRFAN BIN AZIZ | C7: =IF(COUNTIF($C$2:C6,"M")>=55,"F",IF(COUNTIF($C$2:C6,"F")>=54,"M",IF(RAND()<55/109,"M","F"))) -> M | D7: =RANDBETWEEN(18,60) -> 47 | E7: =CHOOSE(RANDBETWEEN(1,9),"WNP","WPS","WPC","ENP","EPS","EPC","TNP","TPS","TPC") -> TPC | F7: =IF(LEFT(E7,1)="W","N/A",CHOOSE(RANDBETWEEN(1,5),5,10,15,20,25)) -> 20 | G7: =CHOOSE(RANDBETWEEN(1,11),50000,60000,75000,80000,100000,120000,125000,150000,175000,180000,200000) -> 120000 | H7: =IF(LEFT(E7,1)="W",CHOOSE(RANDBETWEEN(1,5),5,10,15,20,25),RANDBETWEEN(1,F7/5)*5) -> 5 | I7: =IF(RIGHT(E7,2)="NP","None",IF(RIGHT(E7,1)="S","SRB","CRB")) -> CRB | J7: =IF(I7="None",0%,5%) -> 0.05 | K7: =IF(LEFT(E7,1)="W",RANDBETWEEN(1,10),RANDBETWEEN(1,MIN(10,F7))) -> 5
A8: 7 | B8: {=IF(C8="M",INDEX('Random Lists'!$A$2:$A$56,COUNTIF($C$2:C8,"M")),INDEX('Random Lists'!$B$2:$B$55,COUNTIF($C$2:C8,"F")))} -> AHMAD LUQMAN BIN AZHAR | C8: =IF(COUNTIF($C$2:C7,"M")>=55,"F",IF(COUNTIF($C$2:C7,"F")>=54,"M",IF(RAND()<55/109,"M","F"))) -> M | D8: =RANDBETWEEN(18,60) -> 50 | E8: =CHOOSE(RANDBETWEEN(1,9),"WNP","WPS","WPC","ENP","EPS","EPC","TNP","TPS","TPC") -> TPC | F8: =IF(LEFT(E8,1)="W","N/A",CHOOSE(RANDBETWEEN(1,5),5,10,15,20,25)) -> 10 | G8: =CHOOSE(RANDBETWEEN(1,11),50000,60000,75000,80000,100000,120000,125000,150000,175000,180000,200000) -> 200000 | H8: =IF(LEFT(E8,1)="W",CHOOSE(RANDBETWEEN(1,5),5,10,15,20,25),RANDBETWEEN(1,F8/5)*5) -> 10 | I8: =IF(RIGHT(E8,2)="NP","None",IF(RIGHT(E8,1)="S","SRB","CRB")) -> CRB | J8: =IF(I8="None",0%,5%) -> 0.05 | K8: =IF(LEFT(E8,1)="W",RANDBETWEEN(1,10),RANDBETWEEN(1,MIN(10,F8))) -> 10
A9: 8 | B9: {=IF(C9="M",INDEX('Random Lists'!$A$2:$A$56,COUNTIF($C$2:C9,"M")),INDEX('Random Lists'!$B$2:$B$55,COUNTIF($C$2:C9,"F")))} -> NUR ALIA BINTI RAZALI | C9: =IF(COUNTIF($C$2:C8,"M")>=55,"F",IF(COUNTIF($C$2:C8,"F")>=54,"M",IF(RAND()<55/109,"M","F"))) -> F | D9: =RANDBETWEEN(18,60) -> 60 | E9: =CHOOSE(RANDBETWEEN(1,9),"WNP","WPS","WPC","ENP","EPS","EPC","TNP","TPS","TPC") -> WPC | F9: =IF(LEFT(E9,1)="W","N/A",CHOOSE(RANDBETWEEN(1,5),5,10,15,20,25)) -> N/A | G9: =CHOOSE(RANDBETWEEN(1,11),50000,60000,75000,80000,100000,120000,125000,150000,175000,180000,200000) -> 150000 | H9: =IF(LEFT(E9,1)="W",CHOOSE(RANDBETWEEN(1,5),5,10,15,20,25),RANDBETWEEN(1,F9/5)*5) -> 5 | I9: =IF(RIGHT(E9,2)="NP","None",IF(RIGHT(E9,1)="S","SRB","CRB")) -> CRB | J9: =IF(I9="None",0%,5%) -> 0.05 | K9: =IF(LEFT(E9,1)="W",RANDBETWEEN(1,10),RANDBETWEEN(1,MIN(10,F9))) -> 1
A10: 9 | B10: {=IF(C10="M",INDEX('Random Lists'!$A$2:$A$56,COUNTIF($C$2:C10,"M")),INDEX('Random Lists'!$B$2:$B$55,COUNTIF($C$2:C10,"F")))} -> NUR HANNA BINTI AZMAN | C10: =IF(COUNTIF($C$2:C9,"M")>=55,"F",IF(COUNTIF($C$2:C9,"F")>=54,"M",IF(RAND()<55/109,"M","F"))) -> F | D10: =RANDBETWEEN(18,60) -> 28 | E10: =CHOOSE(RANDBETWEEN(1,9),"WNP","WPS","WPC","ENP","EPS","EPC","TNP","TPS","TPC") -> WPC | F10: =IF(LEFT(E10,1)="W","N/A",CHOOSE(RANDBETWEEN(1,5),5,10,15,20,25)) -> N/A | G10: =CHOOSE(RANDBETWEEN(1,11),50000,60000,75000,80000,100000,120000,125000,150000,175000,180000,200000) -> 75000 | H10: =IF(LEFT(E10,1)="W",CHOOSE(RANDBETWEEN(1,5),5,10,15,20,25),RANDBETWEEN(1,F10/5)*5) -> 5 | I10: =IF(RIGHT(E10,2)="NP","None",IF(RIGHT(E10,1)="S","SRB","CRB")) -> CRB | J10: =IF(I10="None",0%,5%) -> 0.05 | K10: =IF(LEFT(E10,1)="W",RANDBETWEEN(1,10),RANDBETWEEN(1,MIN(10,F10))) -> 9
A11: 10 | B11: {=IF(C11="M",INDEX('Random Lists'!$A$2:$A$56,COUNTIF($C$2:C11,"M")),INDEX('Random Lists'!$B$2:$B$55,COUNTIF($C$2:C11,"F")))} -> NUR HAZREENA BINTI JAMAL | C11: =IF(COUNTIF($C$2:C10,"M")>=55,"F",IF(COUNTIF($C$2:C10,"F")>=54,"M",IF(RAND()<55/109,"M","F"))) -> F | D11: =RANDBETWEEN(18,60) -> 59 | E11: =CHOOSE(RANDBETWEEN(1,9),"WNP","WPS","WPC","ENP","EPS","EPC","TNP","TPS","TPC") -> TPC | F11: =IF(LEFT(E11,1)="W","N/A",CHOOSE(RANDBETWEEN(1,5),5,10,15,20,25)) -> 10 | G11: =CHOOSE(RANDBETWEEN(1,11),50000,60000,75000,80000,100000,120000,125000,150000,175000,180000,200000) -> 120000 | H11: =IF(LEFT(E11,1)="W",CHOOSE(RANDBETWEEN(1,5),5,10,15,20,25),RANDBETWEEN(1,F11/5)*5) -> 10 | I11: =IF(RIGHT(E11,2)="NP","None",IF(RIGHT(E11,1)="S","SRB","CRB")) -> CRB | J11: =IF(I11="None",0%,5%) -> 0.05 | K11: =IF(LEFT(E11,1)="W",RANDBETWEEN(1,10),RANDBETWEEN(1,MIN(10,F11))) -> 5
A12: 11 | B12: {=IF(C12="M",INDEX('Random Lists'!$A$2:$A$56,COUNTIF($C$2:C12,"M")),INDEX('Random Lists'!$B$2:$B$55,COUNTIF($C$2:C12,"F")))} -> NUR MAISARAH BINTI ZAINAL | C12: =IF(COUNTIF($C$2:C11,"M")>=55,"F",IF(COUNTIF($C$2:C11,"F")>=54,"M",IF(RAND()<55/109,"M","F"))) -> F | D12: =RANDBETWEEN(18,60) -> 51 | E12: =CHOOSE(RANDBETWEEN(1,9),"WNP","WPS","WPC","ENP","EPS","EPC","TNP","TPS","TPC") -> EPC | F12: =IF(LEFT(E12,1)="W","N/A",CHOOSE(RANDBETWEEN(1,5),5,10,15,20,25)) -> 15 | G12: =CHOOSE(RANDBETWEEN(1,11),50000,60000,75000,80000,100000,120000,125000,150000,175000,180000,200000) -> 80000 | H12: =IF(LEFT(E12,1)="W",CHOOSE(RANDBETWEEN(1,5),5,10,15,20,25),RANDBETWEEN(1,F12/5)*5) -> 15 | I12: =IF(RIGHT(E12,2)="NP","None",IF(RIGHT(E12,1)="S","SRB","CRB")) -> CRB | J12: =IF(I12="None",0%,5%) -> 0.05 | K12: =IF(LEFT(E12,1)="W",RANDBETWEEN(1,10),RANDBETWEEN(1,MIN(10,F12))) -> 1
A13: 12 | B13: {=IF(C13="M",INDEX('Random Lists'!$A$2:$A$56,COUNTIF($C$2:C13,"M")),INDEX('Random Lists'!$B$2:$B$55,COUNTIF($C$2:C13,"F")))} -> AMIR SYAKIR BIN ZAIDI | C13: =IF(COUNTIF($C$2:C12,"M")>=55,"F",IF(COUNTIF($C$2:C12,"F")>=54,"M",IF(RAND()<55/109,"M","F"))) -> M | D13: =RANDBETWEEN(18,60) -> 33 | E13: =CHOOSE(RANDBETWEEN(1,9),"WNP","WPS","WPC","ENP","EPS","EPC","TNP","TPS","TPC") -> TPC | F13: =IF(LEFT(E13,1)="W","N/A",CHOOSE(RANDBETWEEN(1,5),5,10,15,20,25)) -> 5 | G13: =CHOOSE(RANDBETWEEN(1,11),50000,60000,75000,80000,100000,120000,125000,150000,175000,180000,200000) -> 100000 | H13: =IF(LEFT(E13,1)="W",CHOOSE(RANDBETWEEN(1,5),5,10,15,20,25),RANDBETWEEN(1,F13/5)*5) -> 5 | I13: =IF(RIGHT(E13,2)="NP","None",IF(RIGHT(E13,1)="S","SRB","CRB")) -> CRB | J13: =IF(I13="None",0%,5%) -> 0.05 | K13: =IF(LEFT(E13,1)="W",RANDBETWEEN(1,10),RANDBETWEEN(1,MIN(10,F13))) -> 3
A14: 13 | B14: {=IF(C14="M",INDEX('Random Lists'!$A$2:$A$56,COUNTIF($C$2:C14,"M")),INDEX('Random Lists'!$B$2:$B$55,COUNTIF($C$2:C14,"F")))} -> SITI NURZAHIRAH BINTI OMAR | C14: =IF(COUNTIF($C$2:C13,"M")>=55,"F",IF(COUNTIF($C$2:C13,"F")>=54,"M",IF(RAND()<55/109,"M","F"))) -> F | D14: =RANDBETWEEN(18,60) -> 46 | E14: =CHOOSE(RANDBETWEEN(1,9),"WNP","WPS","WPC","ENP","EPS","EPC","TNP","TPS","TPC") -> TPC | F14: =IF(LEFT(E14,1)="W","N/A",CHOOSE(RANDBETWEEN(1,5),5,10,15,20,25)) -> 20 | G14: =CHOOSE(RANDBETWEEN(1,11),50000,60000,75000,80000,100000,120000,125000,150000,175000,180000,200000) -> 75000 | H14: =IF(LEFT(E14,1)="W",CHOOSE(RANDBETWEEN(1,5),5,10,15,20,25),RANDBETWEEN(1,F14/5)*5) -> 15 | I14: =IF(RIGHT(E14,2)="NP","None",IF(RIGHT(E14,1)="S","SRB","CRB")) -> CRB | J14: =IF(I14="None",0%,5%) -> 0.05 | K14: =IF(LEFT(E14,1)="W",RANDBETWEEN(1,10),RANDBETWEEN(1,MIN(10,F14))) -> 5
... A110: 109 | B110: {=IF(C110="M",INDEX('Random Lists'!$A$2:$A$56,COUNTIF($C$2:C110,"M")),INDEX('Random Lists'!$B$2:$B$55,COUNTIF($C$2:C110,"F")))} -> SITI HAZIRAH BINTI AZIZ | C110: =IF(COUNTIF($C$2:C109,"M")>=55,"F",IF(COUNTIF($C$2:C109,"F")>=54,"M",IF(RAND()<55/109,"M","F"))) -> F | D110: =RANDBETWEEN(18,60) -> 26 | E110: =CHOOSE(RANDBETWEEN(1,9),"WNP","WPS","WPC","ENP","EPS","EPC","TNP","TPS","TPC") -> EPS | F110: =IF(LEFT(E110,1)="W","N/A",CHOOSE(RANDBETWEEN(1,5),5,10,15,20,25)) -> 5 | G110: =CHOOSE(RANDBETWEEN(1,11),50000,60000,75000,80000,100000,120000,125000,150000,175000,180000,200000) -> 175000 | H110: =IF(LEFT(E110,1)="W",CHOOSE(RANDBETWEEN(1,5),5,10,15,20,25),RANDBETWEEN(1,F110/5)*5) -> 5 | I110: =IF(RIGHT(E110,2)="NP","None",IF(RIGHT(E110,1)="S","SRB","CRB")) -> SRB | J110: =IF(I110="None",0%,5%) -> 0.05 | K110: =IF(LEFT(E110,1)="W",RANDBETWEEN(1,10),RANDBETWEEN(1,MIN(10,F110))) -> 1

Sheet Random Lists
A1: Randomized Male Names | B1: Randomized Female Names | D1: Policy Code | E1: Meaning
A2: MUHAMMAD HAZIQ BIN SHAH | B2: NURUL HUSNA BINTI SHAH | D2: WNP | E2: Whole Life – Non-Participating
A3: MUHAMMAD HAZWAN BIN RAMLI | B3: NUR SYAZWANI BINTI SALLEH | D3: WPS | E3: Whole Life – Participating – Simple Reversionary Bonus
A4: MUHAMMAD IRFAN BIN AZIZ | B4: NUR SHAFIQAH BINTI MAHADI | D4: WPC | E4: Whole Life – Participating – Compound Reversionary Bonus
A5: AHMAD LUQMAN BIN AZHAR | B5: NUR ALIA BINTI RAZALI | D5: ENP | E5: Endowment – Non-Participating
A6: AMIR SYAKIR BIN ZAIDI | B6: NUR HANNA BINTI AZMAN | D6: EPS | E6: Endowment – Participating – Simple Reversionary Bonus
A7: MUHAMMAD SHAFIQ BIN MAHADI | B7: NUR HAZREENA BINTI JAMAL | D7: EPC | E7: Endowment – Participating – Compound Reversionary Bonus
A8: MUHAMMAD RAYYAN BIN HISHAM | B8: NUR MAISARAH BINTI ZAINAL | D8: TNP | E8: Term – Non-Participating
A9: MUHAMMAD IKRAM BIN MUSTAFA | B9: SITI NURZAHIRAH BINTI OMAR | D9: TPS | E9: Term – Participating – Simple Reversionary Bonus
A10: MUHAMMAD SYAFIQ BIN JAMAL | B10: NUR HAZWANI BINTI ROSLAN | D10: TPC | E10: Term – Participating – Compound Reversionary Bonus
A11: MUHAMMAD FIKRI BIN NASIR | B11: SITI NURUL AIN BINTI RAHIM
A12: MUHAMMAD DANIAL BIN ZAKI | B12: NUR HAFIZAH BINTI ZULKIFLI
A13: AHMAD SYAMIL BIN RAHMAN | B13: NUR ADALIA BINTI HASSAN
A14: MUHAMMAD HAZIM BIN YUSOF | B14: SITI NUR AMIRAH BINTI RAZAK
A15: MUHAMMAD HARITH BIN ZULKIFLI | B15: NUR AFIQAH BINTI ZAIDI
A16: MUHAMMAD NAUFAL BIN RAHMAN | B16: NUR DANIA BINTI RAHMAN
A17: AHMAD SYAHMI BIN RAZALI | B17: NUR RAIHANA BINTI HISHAM
A18: MUHAMMAD AFIQ BIN ZUL | B18: NURUL HUDA BINTI RAHMAN
A19: AHMAD NAIM BIN AZIZ | B19: NUR AINUL SYAFIQAH BINTI RAHMAN
A20: MUHAMMAD ALIF BIN RAZALI | B20: NUR SYAHIDA BINTI AZMAN
A21: MUHAMMAD SHAHMI BIN AZIZ | B21: NURUL SYAFINA BINTI SHUKRI
A22: MUHAMMAD ASYRAF BIN ZAINAL | B22: NURUL IKMAL BINTI MUSTAFA
... A55: MUHAMMAD FARHAN BIN KHALID | B55: SITI HAZIRAH BINTI AZIZ
A56: AHMAD ZIKRI BIN ISMAIL

Sheet DGI TABLE
A1: x | B1: qx | C1: Dx | D1: Nx | E1: Sx | F1: Cx | G1: Mx | H1: Rx
A2: 10 | B2: 0.00157 | C2: 6755641.7 | D2: 155874750 | E2: 3130429877 | F2: 10198.42 | G2: 759934.67 | H2: 35426412
A3: 11 | B3: 0.00156 | C3: 6485610.9 | D3: 1.4911911e+08 | E3: 2974555127 | F3: 9728.42 | G3: 749736.25 | H3: 34666477
A4: 12 | B4: 0.00149 | C4: 6226435.9 | D4: 1.426335e+08 | E4: 2.825436e+09 | F4: 8920.57 | G4: 740007.84 | H4: 33916741
A5: 13 | B5: 0.00145 | C5: 5978037 | D5: 1.3640706e+08 | E5: 2.6828025e+09 | F5: 8334.76 | G5: 731087.27 | H5: 33176733
A6: 14 | B6: 0.00144 | C6: 5739777.8 | D6: 1.3042902e+08 | E6: 2.5463955e+09 | F6: 7947.38 | G6: 722752.51 | H6: 32445646
A7: 15 | B7: 0.00144 | C7: 5511069.7 | D7: 1.2468925e+08 | E7: 2.4159664e+09 | F7: 7630.71 | G7: 714805.12 | H7: 31722893
A8: 16 | B8: 0.00148 | C8: 5291474.8 | D8: 119178177 | E8: 2.2912772e+09 | F8: 7530.18 | G8: 707174.41 | H8: 31008088
A9: 17 | B9: 0.00154 | C9: 5080426.3 | D9: 1.138867e+08 | E9: 2.172099e+09 | F9: 7522.94 | G9: 699644.23 | H9: 30300914
A10: 18 | B10: 0.00163 | C10: 4877502.4 | D10: 1.0880628e+08 | E10: 2.0582123e+09 | F10: 7644.55 | G10: 692121.29 | H10: 29601270
A11: 19 | B11: 0.00176 | C11: 4682261.6 | D11: 1.0392877e+08 | E11: 1.949406e+09 | F11: 7923.83 | G11: 684476.75 | H11: 28909148
A12: 20 | B12: 0.0019 | C12: 4494250.8 | D12: 99246512 | E12: 1.8454773e+09 | F12: 8210.65 | G12: 676552.92 | H12: 28224672
A13: 21 | B13: 0.00207 | C13: 4313184.3 | D13: 94752261 | E13: 1.7462307e+09 | F13: 8584.9 | G13: 668342.27 | H13: 27548119
... A91: 99 | B91: 0.42513 | C91: 948.6 | D91: 948.6 | E91: 948.6 | F91: 387.75 | G91: 387.75 | H91: 387.75

Sheet Policyholder Data
A1: No. | B1: Name | C1: Gender | D1: Age at Issue, x | E1: Policy | F1: Policy Term, n | G1: Sum Assured | H1: Premium Term, h | I1: Type of Bonus | J1: Bonus % | K1: Time Since Inception, t | L1: Valuation Age at Issue DGI96 | M1: APV of Benefit | N1: APV of Premium | O1: Net Premium | P1: Ax+1:n-1 | Q1: ax+1:h-1 | R1: αF | S1: βF | T1: βZ | U1: min(βF,βZ) | V1: Ax+t:n-t | W1: ax+t:h-t | X1: Reserve at time t | Y1: Average Reserve
A2: 1 | B2: NURUL HUDA BINTI RAHMAN | C2: F | D2: 44 | E2: ENP | F2: 20 | G2: 60000 | H2: 10 | I2: None | J2: 0 | K2: 4 | L2: =IF(C2="F",D2-3,D2) -> 41 | M2: =(_xlfn.XLOOKUP(L2,'DGI TABLE'!$A$2:$A$91,'DGI TABLE'!$G$2:$G$91)-_xlfn.XLOOKUP(L2+F2,'DGI TABLE'!$A$2:$A$91,'DGI TABLE'!$G$2:$G$91)+_xlfn.XLOOKUP(L2+F2,'DGI TABLE'!$A$2:$A$91,'DGI TABLE'!$C$2:$C$91))/_xlfn.XLOOKUP(L2,'DGI TABLE'!$A$2:$A$91,'DGI TABLE'!$C$2:$C$91) -> 0.47904 | N2: =(_xlfn.XLOOKUP(L2,'DGI TABLE'!$A$2:$A$91,'DGI TABLE'!$D$2:$D$91)-_xlfn.XLOOKUP(L2+H2,'DGI TABLE'!$A$2:$A$91,'DGI TABLE'!$D$2:$D$91))/_xlfn.XLOOKUP(L2,'DGI TABLE'!$A$2:$A$91,'DGI TABLE'!$C$2:$C$91) -> 8.3041837 | O2: =M2/N2 -> 0.057686585 | P2: =(_xlfn.XLOOKUP(L2+1,'DGI TABLE'!$A$2:$A$91,'DGI TABLE'!$G$2:$G$91)-_xlfn.XLOOKUP(L2+F2,'DGI TABLE'!$A$2:$A$91,'DGI TABLE'!$G$2:$G$91))/_xlfn.XLOOKUP(L2+1,'DGI TABLE'!$A$2:$A$91,'DGI TABLE'!$C$2:$C$91) -> 0.088875562 | Q2: =(_xlfn.XLOOKUP(L2+1,'DGI TABLE'!$A$2:$A$91,'DGI TABLE'!$D$2:$D$91)-_xlfn.XLOOKUP(L2+H2,'DGI TABLE'!$A$2:$A$91,'DGI TABLE'!$D$2:$D$91))/_xlfn.XLOOKUP(L2+1,'DGI TABLE'!$A$2:$A$91,'DGI TABLE'!$C$2:$C$91) -> 7.618674 | R2: =_xlfn.XLOOKUP(L2,'DGI TABLE'!$A$2:$A$91,'DGI TABLE'!$F$2:$F$91)/_xlfn.XLOOKUP(L2,'DGI TABLE'!$A$2:$A$91,'DGI TABLE'!$C$2:$C$91) -> 0.0028173098 | S2: =P2/Q2 -> 0.01166549 | T2: =O2+0.03/N2 -> 0.061299222 | U2: =MIN(S2,T2) -> 0.01166549 | V2: =(_xlfn.XLOOKUP(L2+K2,'DGI TABLE'!$A$2:$A$91,'DGI TABLE'!$G$2:$G$91)-_xlfn.XLOOKUP(L2+F2,'DGI TABLE'!$A$2:$A$91,'DGI TABLE'!$G$2:$G$91))/_xlfn.XLOOKUP(L2+K2,'DGI TABLE'!$A$2:$A$91,'DGI TABLE'!$C$2:$C$91) -> 0.090043189 | W2: =(_xlfn.XLOOKUP(L2+K2,'DGI TABLE'!$A$2:$A$91,'DGI TABLE'!$D$2:$D$91)-_xlfn.XLOOKUP(L2+H2,'DGI TABLE'!$A$2:$A$91,'DGI TABLE'!$D$2:$D$91))/_xlfn.XLOOKUP(L2+K2,'DGI TABLE'!$A$2:$A$91,'DGI TABLE'!$C$2:$C$91) -> 5.3903487 | X2: =G2*(V2-(U2*W2)) -> 1629.7279 | Y2: =AVERAGE(X2:X44) -> 3707.8759
A3: 2 | B3: MUHAMMAD HAZIM BIN YUSOF | C3: M | D3: 35 | E3: ENP | F3: 10 | G3: 180000 | H3: 5 | I3: None | J3: 0 | K3: 3 | L3: =IF(C3="F",D3-3,D3) -> 35 | M3: =(_xlfn.XLOOKUP(L3,'DGI TABLE'!$A$2:$A$91,'DGI TABLE'!$G$2:$G$91)-_xlfn.XLOOKUP(L3+F3,'DGI TABLE'!$A$2:$A$91,'DGI TABLE'!$G$2:$G$91)+_xlfn.XLOOKUP(L3+F3,'DGI TABLE'!$A$2:$A$91,'DGI TABLE'!$C$2:$C$91))/_xlfn.XLOOKUP(L3,'DGI TABLE'!$A$2:$A$91,'DGI TABLE'!$C$2:$C$91) -> 0.67876569 | N3: =(_xlfn.XLOOKUP(L3,'DGI TABLE'!$A$2:$A$91,'DGI TABLE'!$D$2:$D$91)-_xlfn.XLOOKUP(L3+H3,'DGI TABLE'!$A$2:$A$91,'DGI TABLE'!$D$2:$D$91))/_xlfn.XLOOKUP(L3,'DGI TABLE'!$A$2:$A$91,'DGI TABLE'!$C$2:$C$91) -> 4.6109095 | O3: =M3/N3 -> 0.14720863 | P3: =(_xlfn.XLOOKUP(L3+1,'DGI TABLE'!$A$2:$A$91,'DGI TABLE'!$G$2:$G$91)-_xlfn.XLOOKUP(L3+F3,'DGI TABLE'!$A$2:$A$91,'DGI TABLE'!$G$2:$G$91))/_xlfn.XLOOKUP(L3+1,'DGI TABLE'!$A$2:$A$91,'DGI TABLE'!$C$2:$C$91) -> 0.020442631 | Q3: =(_xlfn.XLOOKUP(L3+1,'DGI TABLE'!$A$2:$A$91,'DGI TABLE'!$D$2:$D$91)-_xlfn.XLOOKUP(L3+H3,'DGI TABLE'!$A$2:$A$91,'DGI TABLE'!$D$2:$D$91))/_xlfn.XLOOKUP(L3+1,'DGI TABLE'!$A$2:$A$91,'DGI TABLE'!$C$2:$C$91) -> 3.762947 | R3: =_xlfn.XLOOKUP(L3,'DGI TABLE'!$A$2:$A$91,'DGI TABLE'!$F$2:$F$91)/_xlfn.XLOOKUP(L3,'DGI TABLE'!$A$2:$A$91,'DGI TABLE'!$C$2:$C$91) -> 0.0019423062 | S3: =P3/Q3 -> 0.0054326119 | T3: =O3+0.03/N3 -> 0.15371494 | U3: =MIN(S3,T3) -> 0.0054326119 | V3: =(_xlfn.XLOOKUP(L3+K3,'DGI TABLE'!$A$2:$A$91,'DGI TABLE'!$G$2:$G$91)-_xlfn.XLOOKUP(L3+F3,'DGI TABLE'!$A$2:$A$91,'DGI TABLE'!$G$2:$G$91))/_xlfn.XLOOKUP(L3+K3,'DGI TABLE'!$A$2:$A$91,'DGI TABLE'!$C$2:$C$91) -> 0.017707815 | W3: =(_xlfn.XLOOKUP(L3+K3,'DGI TABLE'!$A$2:$A$91,'DGI TABLE'!$D$2:$D$91)-_xlfn.XLOOKUP(L3+H3,'DGI TABLE'!$A$2:$A$91,'DGI TABLE'!$D$2:$D$91))/_xlfn.XLOOKUP(L3+K3,'DGI TABLE'!$A$2:$A$91,'DGI TABLE'!$C$2:$C$91) -> 1.9592404 | X3: =G3*(V3-(U3*W3)) -> 1271.524
A4: 3 | B4: NUR DANIAH BINTI ZAKI | C4: F | D4: 30 | E4: ENP | F4: 10 | G4: 150000 | H4: 5 | I4: None | J4: 0 | K4: 2 | L4: =IF(C4="F",D4-3,D4) -> 27 | M4: =(_xlfn.XLOOKUP(L4,'DGI TABLE'!$A$2:$A$91,'DGI TABLE'!$G$2:$G$91)-_xlfn.XLOOKUP(L4+F4,'DGI TABLE'!$A$2:$A$91,'DGI TABLE'!$G$2:$G$91)+_xlfn.XLOOKUP(L4+F4,'DGI TABLE'!$A$2:$A$91,'DGI TABLE'!$C$2:$C$91))/_xlfn.XLOOKUP(L4,'DGI TABLE'!$A$2:$A$91,'DGI TABLE'!$C$2:$C$91) -> 0.67805606 | N4: =(_xlfn.XLOOKUP(L4,'DGI TABLE'!$A$2:$A$91,'DGI TABLE'!$D$2:$D$91)-_xlfn.XLOOKUP(L4+H4,'DGI TABLE'!$A$2:$A$91,'DGI TABLE'!$D$2:$D$91))/_xlfn.XLOOKUP(L4,'DGI TABLE'!$A$2:$A$91,'DGI TABLE'!$C$2:$C$91) -> 4.6132708 | O4: =M4/N4 -> 0.14697946 | P4: =(_xlfn.XLOOKUP(L4+1,'DGI TABLE'!$A$2:$A$91,'DGI TABLE'!$G$2:$G$91)-_xlfn.XLOOKUP(L4+F4,'DGI TABLE'!$A$2:$A$91,'DGI TABLE'!$G$2:$G$91))/_xlfn.XLOOKUP(L4+1,'DGI TABLE'!$A$2:$A$91,'DGI TABLE'!$C$2:$C$91) -> 0.013857827 | Q4: =(_xlfn.XLOOKUP(L4+1,'DGI TABLE'!$A$2:$A$91,'DGI TABLE'!$D$2:$D$91)-_xlfn.XLOOKUP(L4+H4,'DGI TABLE'!$A$2:$A$91,'DGI TABLE'!$D$2:$D$91))/_xlfn.XLOOKUP(L4+1,'DGI TABLE'!$A$2:$A$91,'DGI TABLE'!$C$2:$C$91) -> 3.7650305 | R4: =_xlfn.XLOOKUP(L4,'DGI TABLE'!$A$2:$A$91,'DGI TABLE'!$F$2:$F$91)/_xlfn.XLOOKUP(L4,'DGI TABLE'!$A$2:$A$91,'DGI TABLE'!$C$2:$C$91) -> 0.0018461549 | S4: =P4/Q4 -> 0.0036806679 | T4: =O4+0.03/N4 -> 0.15348244 | U4: =MIN(S4,T4) -> 0.0036806679 | V4: =(_xlfn.XLOOKUP(L4+K4,'DGI TABLE'!$A$2:$A$91,'DGI TABLE'!$G$2:$G$91)-_xlfn.XLOOKUP(L4+F4,'DGI TABLE'!$A$2:$A$91,'DGI TABLE'!$G$2:$G$91))/_xlfn.XLOOKUP(L4+K4,'DGI TABLE'!$A$2:$A$91,'DGI TABLE'!$C$2:$C$91) -> 0.012565637 | W4: =(_xlfn.XLOOKUP(L4+K4,'DGI TABLE'!$A$2:$A$91,'DGI TABLE'!$D$2:$D$91)-_xlfn.XLOOKUP(L4+H4,'DGI TABLE'!$A$2:$A$91,'DGI TABLE'!$D$2:$D$91))/_xlfn.XLOOKUP(L4+K4,'DGI TABLE'!$A$2:$A$91,'DGI TABLE'!$C$2:$C$91) -> 2.8810193 | X4: =G4*(V4-(U4*W4)) -> 294.23424
A5: 4 | B5: MUHAMMAD ALIF BIN RAZALI | C5: M | D5: 49 | E5: ENP | F5: 10 | G5: 125000 | H5: 3 | I5: None | J5: 0 | K5: 2 | L5: =IF(C5="F",D5-3,D5) -> 49 | M5: =(_xlfn.XLOOKUP(L5,'DGI TABLE'!$A$2:$A$91,'DGI TABLE'!$G$2:$G$91)-_xlfn.XLOOKUP(L5+F5,'DGI TABLE'!$A$2:$A$91,'DGI TABLE'!$G$2:$G$91)+_xlfn.XLOOKUP(L5+F5,'DGI TABLE'!$A$2:$A$91,'DGI TABLE'!$C$2:$C$91))/_xlfn.XLOOKUP(L5,'DGI TABLE'!$A$2:$A$91,'DGI TABLE'!$C$2:$C$91) -> 0.68583118 | N5: =(_xlfn.XLOOKUP(L5,'DGI TABLE'!$A$2:$A$91,'DGI TABLE'!$D$2:$D$91)-_xlfn.XLOOKUP(L5+H5,'DGI TABLE'!$A$2:$A$91,'DGI TABLE'!$D$2:$D$91))/_xlfn.XLOOKUP(L5,'DGI TABLE'!$A$2:$A$91,'DGI TABLE'!$C$2:$C$91) -> 2.8686562 | O5: =M5/N5 -> 0.23907751 | P5: =(_xlfn.XLOOKUP(L5+1,'DGI TABLE'!$A$2:$A$91,'DGI TABLE'!$G$2:$G$91)-_xlfn.XLOOKUP(L5+F5,'DGI TABLE'!$A$2:$A$91,'DGI TABLE'!$G$2:$G$91))/_xlfn.XLOOKUP(L5+1,'DGI TABLE'!$A$2:$A$91,'DGI TABLE'!$C$2:$C$91) -> 0.067394531 | Q5: =(_xlfn.XLOOKUP(L5+1,'DGI TABLE'!$A$2:$A$91,'DGI TABLE'!$D$2:$D$91)-_xlfn.XLOOKUP(L5+H5,'DGI TABLE'!$A$2:$A$91,'DGI TABLE'!$D$2:$D$91))/_xlfn.XLOOKUP(L5+1,'DGI TABLE'!$A$2:$A$91,'DGI TABLE'!$C$2:$C$91) -> 1.9551924 | R5: =_xlfn.XLOOKUP(L5,'DGI TABLE'!$A$2:$A$91,'DGI TABLE'!$F$2:$F$91)/_xlfn.XLOOKUP(L5,'DGI TABLE'!$A$2:$A$91,'DGI TABLE'!$C$2:$C$91) -> 0.0057980762 | S5: =P5/Q5 -> 0.034469514 | T5: =O5+0.03/N5 -> 0.24953537 | U5: =MIN(S5,T5) -> 0.034469514 | V5: =(_xlfn.XLOOKUP(L5+K5,'DGI TABLE'!$A$2:$A$91,'DGI TABLE'!$G$2:$G$91)-_xlfn.XLOOKUP(L5+F5,'DGI TABLE'!$A$2:$A$91,'DGI TABLE'!$G$2:$G$91))/_xlfn.XLOOKUP(L5+K5,'DGI TABLE'!$A$2:$A$91,'DGI TABLE'!$C$2:$C$91) -> 0.063912132 | W5: =(_xlfn.XLOOKUP(L5+K5,'DGI TABLE'!$A$2:$A$91,'DGI TABLE'!$D$2:$D$91)-_xlfn.XLOOKUP(L5+H5,'DGI TABLE'!$A$2:$A$91,'DGI TABLE'!$D$2:$D$91))/_xlfn.XLOOKUP(L5+K5,'DGI TABLE'!$A$2:$A$91,'DGI TABLE'!$C$2:$C$91) -> 1.0000001 | X5: =G5*(V5-(U5*W5)) -> 3680.327
A6: 5 | B6: NUR AINUL MARDHIYAH BINTI KAMAL | C6: F | D6: 38 | E6: ENP | F6: 20 | G6: 60000 | H6: 5 | I6: None | J6: 0 | K6: 3 | L6: =IF(C6="F",D6-3,D6) -> 35 | M6: =(_xlfn.XLOOKUP(L6,'DGI TABLE'!$A$2:$A$91,'DGI TABLE'!$G$2:$G$91)-_xlfn.XLOOKUP(L6+F6,'DGI TABLE'!$A$2:$A$91,'DGI TABLE'!$G$2:$G$91)+_xlfn.XLOOKUP(L6+F6,'DGI TABLE'!$A$2:$A$91,'DGI TABLE'!$C$2:$C$91))/_xlfn.XLOOKUP(L6,'DGI TABLE'!$A$2:$A$91,'DGI TABLE'!$C$2:$C$91) -> 0.47028786 | N6: =(_xlfn.XLOOKUP(L6,'DGI TABLE'!$A$2:$A$91,'DGI TABLE'!$D$2:$D$91)-_xlfn.XLOOKUP(L6+H6,'DGI TABLE'!$A$2:$A$91,'DGI TABLE'!$D$2:$D$91))/_xlfn.XLOOKUP(L6,'DGI TABLE'!$A$2:$A$91,'DGI TABLE'!$C$2:$C$91) -> 4.6109095 | O6: =M6/N6 -> 0.1019946 | P6: =(_xlfn.XLOOKUP(L6+1,'DGI TABLE'!$A$2:$A$91,'DGI TABLE'!$G$2:$G$91)-_xlfn.XLOOKUP(L6+F6,'DGI TABLE'!$A$2:$A$91,'DGI TABLE'!$G$2:$G$91))/_xlfn.XLOOKUP(L6+1,'DGI TABLE'!$A$2:$A$91,'DGI TABLE'!$C$2:$C$91) -> 0.054697655 | Q6: =(_xlfn.XLOOKUP(L6+1,'DGI TABLE'!$A$2:$A$91,'DGI TABLE'!$D$2:$D$91)-_xlfn.XLOOKUP(L6+H6,'DGI TABLE'!$A$2:$A$91,'DGI TABLE'!$D$2:$D$91))/_xlfn.XLOOKUP(L6+1,'DGI TABLE'!$A$2:$A$91,'DGI TABLE'!$C$2:$C$91) -> 3.762947 | R6: =_xlfn.XLOOKUP(L6,'DGI TABLE'!$A$2:$A$91,'DGI TABLE'!$F$2:$F$91)/_xlfn.XLOOKUP(L6,'DGI TABLE'!$A$2:$A$91,'DGI TABLE'!$C$2:$C$91) -> 0.0019423062 | S6: =P6/Q6 -> 0.014535856 | T6: =O6+0.03/N6 -> 0.10850091 | U6: =MIN(S6,T6) -> 0.014535856 | V6: =(_xlfn.XLOOKUP(L6+K6,'DGI TABLE'!$A$2:$A$91,'DGI TABLE'!$G$2:$G$91)-_xlfn.XLOOKUP(L6+F6,'DGI TABLE'!$A$2:$A$91,'DGI TABLE'!$G$2:$G$91))/_xlfn.XLOOKUP(L6+K6,'DGI TABLE'!$A$2:$A$91,'DGI TABLE'!$C$2:$C$91) -> 0.054921611 | W6: =(_xlfn.XLOOKUP(L6+K6,'DGI TABLE'!$A$2:$A$91,'DGI TABLE'!$D$2:$D$91)-_xlfn.XLOOKUP(L6+H6,'DGI TABLE'!$A$2:$A$91,'DGI TABLE'!$D$2:$D$91))/_xlfn.XLOOKUP(L6+K6,'DGI TABLE'!$A$2:$A$91,'DGI TABLE'!$C$2:$C$91) -> 1.9592404 | X6: =G6*(V6-(U6*W6)) -> 1586.5425
A7: 6 | B7: SITI NURAINA BINTI RAMLI | C7: F | D7: 51 | E7: ENP | F7: 5 | G7: 75000 | H7: 5 | I7: None | J7: 0 | K7: 4 | L7: =IF(C7="F",D7-3,D7) -> 48 | M7: =(_xlfn.XLOOKUP(L7,'DGI TABLE'!$A$2:$A$91,'DGI TABLE'!$G$2:$G$91)-_xlfn.XLOOKUP(L7+F7,'DGI TABLE'!$A$2:$A$91,'DGI TABLE'!$G$2:$G$91)+_xlfn.XLOOKUP(L7+F7,'DGI TABLE'!$A$2:$A$91,'DGI TABLE'!$C$2:$C$91))/_xlfn.XLOOKUP(L7,'DGI TABLE'!$A$2:$A$91,'DGI TABLE'!$C$2:$C$91) -> 0.8239835 | N7: =(_xlfn.XLOOKUP(L7,'DGI TABLE'!$A$2:$A$91,'DGI TABLE'!$D$2:$D$91)-_xlfn.XLOOKUP(L7+H7,'DGI TABLE'!$A$2:$A$91,'DGI TABLE'!$D$2:$D$91))/_xlfn.XLOOKUP(L7,'DGI TABLE'!$A$2:$A$91,'DGI TABLE'!$C$2:$C$91) -> 4.5764282 | O7: =M7/N7 -> 0.18004948 | P7: =(_xlfn.XLOOKUP(L7+1,'DGI TABLE'!$A$2:$A$91,'DGI TABLE'!$G$2:$G$91)-_xlfn.XLOOKUP(L7+F7,'DGI TABLE'!$A$2:$A$91,'DGI TABLE'!$G$2:$G$91))/_xlfn.XLOOKUP(L7+1,'DGI TABLE'!$A$2:$A$91,'DGI TABLE'!$C$2:$C$91) -> 0.024812171 | Q7: =(_xlfn.XLOOKUP(L7+1,'DGI TABLE'!$A$2:$A$91,'DGI TABLE'!$D$2:$D$91)-_xlfn.XLOOKUP(L7+H7,'DGI TABLE'!$A$2:$A$91,'DGI TABLE'!$D$2:$D$91))/_xlfn.XLOOKUP(L7+1,'DGI TABLE'!$A$2:$A$91,'DGI TABLE'!$C$2:$C$91) -> 3.7401309 | R7: =_xlfn.XLOOKUP(L7,'DGI TABLE'!$A$2:$A$91,'DGI TABLE'!$F$2:$F$91)/_xlfn.XLOOKUP(L7,'DGI TABLE'!$A$2:$A$91,'DGI TABLE'!$C$2:$C$91) -> 0.0053076929 | S7: =P7/Q7 -> 0.0066340381 | T7: =O7+0.03/N7 -> 0.18660481 | U7: =MIN(S7,T7) -> 0.0066340381 | V7: =(_xlfn.XLOOKUP(L7+K7,'DGI TABLE'!$A$2:$A$91,'DGI TABLE'!$G$2:$G$91)-_xlfn.XLOOKUP(L7+F7,'DGI TABLE'!$A$2:$A$91,'DGI TABLE'!$G$2:$G$91))/_xlfn.XLOOKUP(L7+K7,'DGI TABLE'!$A$2:$A$91,'DGI TABLE'!$C$2:$C$91) -> 0.0075961494 | W7: =(_xlfn.XLOOKUP(L7+K7,'DGI TABLE'!$A$2:$A$91,'DGI TABLE'!$D$2:$D$91)-_xlfn.XLOOKUP(L7+H7,'DGI TABLE'!$A$2:$A$91,'DGI TABLE'!$D$2:$D$91))/_xlfn.XLOOKUP(L7+K7,'DGI TABLE'!$A$2:$A$91,'DGI TABLE'!$C$2:$C$91) -> 0.99999991 | X7: =G7*(V7-(U7*W7)) -> 72.15839
A8: 7 | B8: MUHAMMAD DANISH BIN ALI | C8: M | D8: 41 | E8: ENP | F8: 20 | G8: 150000 | H8: 15 | I8: None | J8: 0 | K8: 3 | L8: =IF(C8="F",D8-3,D8) -> 41 | M8: =(_xlfn.XLOOKUP(L8,'DGI TABLE'!$A$2:$A$91,'DGI TABLE'!$G$2:$G$91)-_xlfn.XLOOKUP(L8+F8,'DGI TABLE'!$A$2:$A$91,'DGI TABLE'!$G$2:$G$91)+_xlfn.XLOOKUP(L8+F8,'DGI TABLE'!$A$2:$A$91,'DGI TABLE'!$C$2:$C$91))/_xlfn.XLOOKUP(L8,'DGI TABLE'!$A$2:$A$91,'DGI TABLE'!$C$2:$C$91) -> 0.47904 | N8: =(_xlfn.XLOOKUP(L8,'DGI TABLE'!$A$2:$A$91,'DGI TABLE'!$D$2:$D$91)-_xlfn.XLOOKUP(L8+H8,'DGI TABLE'!$A$2:$A$91,'DGI TABLE'!$D$2:$D$91))/_xlfn.XLOOKUP(L8,'DGI TABLE'!$A$2:$A$91,'DGI TABLE'!$C$2:$C$91) -> 11.247629 | O8: =M8/N8 -> 0.042590311 | P8: =(_xlfn.XLOOKUP(L8+1,'DGI TABLE'!$A$2:$A$91,'DGI TABLE'!$G$2:$G$91)-_xlfn.XLOOKUP(L8+F8,'DGI TABLE'!$A$2:$A$91,'DGI TABLE'!$G$2:$G$91))/_xlfn.XLOOKUP(L8+1,'DGI TABLE'!$A$2:$A$91,'DGI TABLE'!$C$2:$C$91) -> 0.088875562 | Q8: =(_xlfn.XLOOKUP(L8+1,'DGI TABLE'!$A$2:$A$91,'DGI TABLE'!$D$2:$D$91)-_xlfn.XLOOKUP(L8+H8,'DGI TABLE'!$A$2:$A$91,'DGI TABLE'!$D$2:$D$91))/_xlfn.XLOOKUP(L8+1,'DGI TABLE'!$A$2:$A$91,'DGI TABLE'!$C$2:$C$91) -> 10.688853 | R8: =_xlfn.XLOOKUP(L8,'DGI TABLE'!$A$2:$A$91,'DGI TABLE'!$F$2:$F$91)/_xlfn.XLOOKUP(L8,'DGI TABLE'!$A$2:$A$91,'DGI TABLE'!$C$2:$C$91) -> 0.0028173098 | S8: =P8/Q8 -> 0.0083147898 | T8: =O8+0.03/N8 -> 0.045257539 | U8: =MIN(S8,T8) -> 0.0083147898 | V8: =(_xlfn.XLOOKUP(L8+K8,'DGI TABLE'!$A$2:$A$91,'DGI TABLE'!$G$2:$G$91)-_xlfn.XLOOKUP(L8+F8,'DGI TABLE'!$A$2:$A$91,'DGI TABLE'!$G$2:$G$91))/_xlfn.XLOOKUP(L8+K8,'DGI TABLE'!$A$2:$A$91,'DGI TABLE'!$C$2:$C$91) -> 0.089931076 | W8: =(_xlfn.XLOOKUP(L8+K8,'DGI TABLE'!$A$2:$A$91,'DGI TABLE'!$D$2:$D$91)-_xlfn.XLOOKUP(L8+H8,'DGI TABLE'!$A$2:$A$91,'DGI TABLE'!$D$2:$D$91))/_xlfn.XLOOKUP(L8+K8,'DGI TABLE'!$A$2:$A$91,'DGI TABLE'!$C$2:$C$91) -> 9.5061757 | X8: =G8*(V8-(U8*W8)) -> 1633.3835
A9: 8 | B9: AHMAD FAIZ BIN YAHYA | C9: M | D9: 36 | E9: ENP | F9: 5 | G9: 60000 | H9: 3 | I9: None | J9: 0 | K9: 2 | L9: =IF(C9="F",D9-3,D9) -> 36 | M9: =(_xlfn.XLOOKUP(L9,'DGI TABLE'!$A$2:$A$91,'DGI TABLE'!$G$2:$G$91)-_xlfn.XLOOKUP(L9+F9,'DGI TABLE'!$A$2:$A$91,'DGI TABLE'!$G$2:$G$91)+_xlfn.XLOOKUP(L9+F9,'DGI TABLE'!$A$2:$A$91,'DGI TABLE'!$C$2:$C$91))/_xlfn.XLOOKUP(L9,'DGI TABLE'!$A$2:$A$91,'DGI TABLE'!$C$2:$C$91) -> 0.82269986 | N9: =(_xlfn.XLOOKUP(L9,'DGI TABLE'!$A$2:$A$91,'DGI TABLE'!$D$2:$D$91)-_xlfn.XLOOKUP(L9+H9,'DGI TABLE'!$A$2:$A$91,'DGI TABLE'!$D$2:$D$91))/_xlfn.XLOOKUP(L9,'DGI TABLE'!$A$2:$A$91,'DGI TABLE'!$C$2:$C$91) -> 2.8799733 | O9: =M9/N9 -> 0.28566232 | P9: =(_xlfn.XLOOKUP(L9+1,'DGI TABLE'!$A$2:$A$91,'DGI TABLE'!$G$2:$G$91)-_xlfn.XLOOKUP(L9+F9,'DGI TABLE'!$A$2:$A$91,'DGI TABLE'!$G$2:$G$91))/_xlfn.XLOOKUP(L9+1,'DGI TABLE'!$A$2:$A$91,'DGI TABLE'!$C$2:$C$91) -> 0.0089337263 | Q9: =(_xlfn.XLOOKUP(L9+1,'DGI TABLE'!$A$2:$A$91,'DGI TABLE'!$D$2:$D$91)-_xlfn.XLOOKUP(L9+H9,'DGI TABLE'!$A$2:$A$91,'DGI TABLE'!$D$2:$D$91))/_xlfn.XLOOKUP(L9+1,'DGI TABLE'!$A$2:$A$91,'DGI TABLE'!$C$2:$C$91) -> 1.9593654 | R9: =_xlfn.XLOOKUP(L9,'DGI TABLE'!$A$2:$A$91,'DGI TABLE'!$F$2:$F$91)/_xlfn.XLOOKUP(L9,'DGI TABLE'!$A$2:$A$91,'DGI TABLE'!$C$2:$C$91) -> 0.0020576944 | S9: =P9/Q9 -> 0.0045595 | T9: =O9+0.03/N9 -> 0.29607908 | U9: =MIN(S9,T9) -> 0.0045595 | V9: =(_xlfn.XLOOKUP(L9+K9,'DGI TABLE'!$A$2:$A$91,'DGI TABLE'!$G$2:$G$91)-_xlfn.XLOOKUP(L9+F9,'DGI TABLE'!$A$2:$A$91,'DGI TABLE'!$G$2:$G$91))/_xlfn.XLOOKUP(L9+K9,'DGI TABLE'!$A$2:$A$91,'DGI TABLE'!$C$2:$C$91) -> 0.0070469989 | W9: =(_xlfn.XLOOKUP(L9+K9,'DGI TABLE'!$A$2:$A$91,'DGI TABLE'!$D$2:$D$91)-_xlfn.XLOOKUP(L9+H9,'DGI TABLE'!$A$2:$A$91,'DGI TABLE'!$D$2:$D$91))/_xlfn.XLOOKUP(L9+K9,'DGI TABLE'!$A$2:$A$91,'DGI TABLE'!$C$2:$C$91) -> 1 | X9: =G9*(V9-(U9*W9)) -> 149.24994
A10: 9 | B10: AHMAD HAZIQ BIN RAHMAN | C10: M | D10: 60 | E10: ENP | F10: 20 | G10: 50000 | H10: 15 | I10: None | J10: 0 | K10: 3 | L10: =IF(C10="F",D10-3,D10) -> 60 | M10: =(_xlfn.XLOOKUP(L10,'DGI TABLE'!$A$2:$A$91,'DGI TABLE'!$G$2:$G$91)-_xlfn.XLOOKUP(L10+F10,'DGI TABLE'!$A$2:$A$91,'DGI TABLE'!$G$2:$G$91)+_xlfn.XLOOKUP(L10+F10,'DGI TABLE'!$A$2:$A$91,'DGI TABLE'!$C$2:$C$91))/_xlfn.XLOOKUP(L10,'DGI TABLE'!$A$2:$A$91,'DGI TABLE'!$C$2:$C$91) -> 0.5553153 | N10: =(_xlfn.XLOOKUP(L10,'DGI TABLE'!$A$2:$A$91,'DGI TABLE'!$D$2:$D$91)-_xlfn.XLOOKUP(L10+H10,'DGI TABLE'!$A$2:$A$91,'DGI TABLE'!$D$2:$D$91))/_xlfn.XLOOKUP(L10,'DGI TABLE'!$A$2:$A$91,'DGI TABLE'!$C$2:$C$91) -> 10.111465 | O10: =M10/N10 -> 0.054919371 | P10: =(_xlfn.XLOOKUP(L10+1,'DGI TABLE'!$A$2:$A$91,'DGI TABLE'!$G$2:$G$91)-_xlfn.XLOOKUP(L10+F10,'DGI TABLE'!$A$2:$A$91,'DGI TABLE'!$G$2:$G$91))/_xlfn.XLOOKUP(L10+1,'DGI TABLE'!$A$2:$A$91,'DGI TABLE'!$C$2:$C$91) -> 0.35643879 | Q10: =(_xlfn.XLOOKUP(L10+1,'DGI TABLE'!$A$2:$A$91,'DGI TABLE'!$D$2:$D$91)-_xlfn.XLOOKUP(L10+H10,'DGI TABLE'!$A$2:$A$91,'DGI TABLE'!$D$2:$D$91))/_xlfn.XLOOKUP(L10+1,'DGI TABLE'!$A$2:$A$91,'DGI TABLE'!$C$2:$C$91) -> 9.6181773 | R10: =_xlfn.XLOOKUP(L10,'DGI TABLE'!$A$2:$A$91,'DGI TABLE'!$F$2:$F$91)/_xlfn.XLOOKUP(L10,'DGI TABLE'!$A$2:$A$91,'DGI TABLE'!$C$2:$C$91) -> 0.01422115 | S10: =P10/Q10 -> 0.037058871 | T10: =O10+0.03/N10 -> 0.0578863 | U10: =MIN(S10,T10) -> 0.037058871 | V10: =(_xlfn.XLOOKUP(L10+K10,'DGI TABLE'!$A$2:$A$91,'DGI TABLE'!$G$2:$G$91)-_xlfn.XLOOKUP(L10+F10,'DGI TABLE'!$A$2:$A$91,'DGI TABLE'!$G$2:$G$91))/_xlfn.XLOOKUP(L10+K10,'DGI TABLE'!$A$2:$A$91,'DGI TABLE'!$C$2:$C$91) -> 0.36382679 | W10: =(_xlfn.XLOOKUP(L10+K10,'DGI TABLE'!$A$2:$A$91,'DGI TABLE'!$D$2:$D$91)-_xlfn.XLOOKUP(L10+H10,'DGI TABLE'!$A$2:$A$91,'DGI TABLE'!$D$2:$D$91))/_xlfn.XLOOKUP(L10+K10,'DGI TABLE'!$A$2:$A$91,'DGI TABLE'!$C$2:$C$91) -> 8.5821136 | X10: =G10*(V10-(U10*W10)) -> 2289.1673
A11: 10 | B11: NUR HAZIRAH BINTI HALIM | C11: F | D11: 41 | E11: ENP | F11: 25 | G11: 120000 | H11: 20 | I11: None | J11: 0 | K11: 2 | L11: =IF(C11="F",D11-3,D11) -> 38 | M11: =(_xlfn.XLOOKUP(L11,'DGI TABLE'!$A$2:$A$91,'DGI TABLE'!$G$2:$G$91)-_xlfn.XLOOKUP(L11+F11,'DGI TABLE'!$A$2:$A$91,'DGI TABLE'!$G$2:$G$91)+_xlfn.XLOOKUP(L11+F11,'DGI TABLE'!$A$2:$A$91,'DGI TABLE'!$C$2:$C$91))/_xlfn.XLOOKUP(L11,'DGI TABLE'!$A$2:$A$91,'DGI TABLE'!$C$2:$C$91) -> 0.40384099 | N11: =(_xlfn.XLOOKUP(L11,'DGI TABLE'!$A$2:$A$91,'DGI TABLE'!$D$2:$D$91)-_xlfn.XLOOKUP(L11+H11,'DGI TABLE'!$A$2:$A$91,'DGI TABLE'!$D$2:$D$91))/_xlfn.XLOOKUP(L11,'DGI TABLE'!$A$2:$A$91,'DGI TABLE'!$C$2:$C$91) -> 13.676014 | O11: =M11/N11 -> 0.029529145 | P11: =(_xlfn.XLOOKUP(L11+1,'DGI TABLE'!$A$2:$A$91,'DGI TABLE'!$G$2:$G$91)-_xlfn.XLOOKUP(L11+F11,'DGI TABLE'!$A$2:$A$91,'DGI TABLE'!$G$2:$G$91))/_xlfn.XLOOKUP(L11+1,'DGI TABLE'!$A$2:$A$91,'DGI TABLE'!$C$2:$C$91) -> 0.097124849 | Q11: =(_xlfn.XLOOKUP(L11+1,'DGI TABLE'!$A$2:$A$91,'DGI TABLE'!$D$2:$D$91)-_xlfn.XLOOKUP(L11+H11,'DGI TABLE'!$A$2:$A$91,'DGI TABLE'!$D$2:$D$91))/_xlfn.XLOOKUP(L11+1,'DGI TABLE'!$A$2:$A$91,'DGI TABLE'!$C$2:$C$91) -> 13.214637 | R11: =_xlfn.XLOOKUP(L11,'DGI TABLE'!$A$2:$A$91,'DGI TABLE'!$F$2:$F$91)/_xlfn.XLOOKUP(L11,'DGI TABLE'!$A$2:$A$91,'DGI TABLE'!$C$2:$C$91) -> 0.0022980774 | S11: =P11/Q11 -> 0.0073497931 | T11: =O11+0.03/N11 -> 0.031722766 | U11: =MIN(S11,T11) -> 0.0073497931 | V11: =(_xlfn.XLOOKUP(L11+K11,'DGI TABLE'!$A$2:$A$91,'DGI TABLE'!$G$2:$G$91)-_xlfn.XLOOKUP(L11+F11,'DGI TABLE'!$A$2:$A$91,'DGI TABLE'!$G$2:$G$91))/_xlfn.XLOOKUP(L11+K11,'DGI TABLE'!$A$2:$A$91,'DGI TABLE'!$C$2:$C$91) -> 0.098720596 | W11: =(_xlfn.XLOOKUP(L11+K11,'DGI TABLE'!$A$2:$A$91,'DGI TABLE'!$D$2:$D$91)-_xlfn.XLOOKUP(L11+H11,'DGI TABLE'!$A$2:$A$91,'DGI TABLE'!$D$2:$D$91))/_xlfn.XLOOKUP(L11+K11,'DGI TABLE'!$A$2:$A$91,'DGI TABLE'!$C$2:$C$91) -> 12.735571 | X11: =G11*(V11-(U11*W11)) -> 614.01418
A12: 11 | B12: NUR IZZATI BINTI ROSLI | C12: F | D12: 42 | E12: ENP | F12: 10 | G12: 100000 | H12: 7 | I12: None | J12: 0 | K12: 3 | L12: =IF(C12="F",D12-3,D12) -> 39 | M12: =(_xlfn.XLOOKUP(L12,'DGI TABLE'!$A$2:$A$91,'DGI TABLE'!$G$2:$G$91)-_xlfn.XLOOKUP(L12+F12,'DGI TABLE'!$A$2:$A$91,'DGI TABLE'!$G$2:$G$91)+_xlfn.XLOOKUP(L12+F12,'DGI TABLE'!$A$2:$A$91,'DGI TABLE'!$C$2:$C$91))/_xlfn.XLOOKUP(L12,'DGI TABLE'!$A$2:$A$91,'DGI TABLE'!$C$2:$C$91) -> 0.67982078 | N12: =(_xlfn.XLOOKUP(L12,'DGI TABLE'!$A$2:$A$91,'DGI TABLE'!$D$2:$D$91)-_xlfn.XLOOKUP(L12+H12,'DGI TABLE'!$A$2:$A$91,'DGI TABLE'!$D$2:$D$91))/_xlfn.XLOOKUP(L12,'DGI TABLE'!$A$2:$A$91,'DGI TABLE'!$C$2:$C$91) -> 6.1910761 | O12: =M12/N12 -> 0.10980656 | P12: =(_xlfn.XLOOKUP(L12+1,'DGI TABLE'!$A$2:$A$91,'DGI TABLE'!$G$2:$G$91)-_xlfn.XLOOKUP(L12+F12,'DGI TABLE'!$A$2:$A$91,'DGI TABLE'!$G$2:$G$91))/_xlfn.XLOOKUP(L12+1,'DGI TABLE'!$A$2:$A$91,'DGI TABLE'!$C$2:$C$91) -> 0.028248847 | Q12: =(_xlfn.XLOOKUP(L12+1,'DGI TABLE'!$A$2:$A$91,'DGI TABLE'!$D$2:$D$91)-_xlfn.XLOOKUP(L12+H12,'DGI TABLE'!$A$2:$A$91,'DGI TABLE'!$D$2:$D$91))/_xlfn.XLOOKUP(L12+1,'DGI TABLE'!$A$2:$A$91,'DGI TABLE'!$C$2:$C$91) -> 5.4124667 | R12: =_xlfn.XLOOKUP(L12,'DGI TABLE'!$A$2:$A$91,'DGI TABLE'!$F$2:$F$91)/_xlfn.XLOOKUP(L12,'DGI TABLE'!$A$2:$A$91,'DGI TABLE'!$C$2:$C$91) -> 0.0024423096 | S12: =P12/Q12 -> 0.0052192186 | T12: =O12+0.03/N12 -> 0.11465225 | U12: =MIN(S12,T12) -> 0.0052192186 | V12: =(_xlfn.XLOOKUP(L12+K12,'DGI TABLE'!$A$2:$A$91,'DGI TABLE'!$G$2:$G$91)-_xlfn.XLOOKUP(L12+F12,'DGI TABLE'!$A$2:$A$91,'DGI TABLE'!$G$2:$G$91))/_xlfn.XLOOKUP(L12+K12,'DGI TABLE'!$A$2:$A$91,'DGI TABLE'!$C$2:$C$91) -> 0.024943853 | W12: =(_xlfn.XLOOKUP(L12+K12,'DGI TABLE'!$A$2:$A$91,'DGI TABLE'!$D$2:$D$91)-_xlfn.XLOOKUP(L12+H12,'DGI TABLE'!$A$2:$A$91,'DGI TABLE'!$D$2:$D$91))/_xlfn.XLOOKUP(L12+K12,'DGI TABLE'!$A$2:$A$91,'DGI TABLE'!$C$2:$C$91) -> 3.7565473 | X12: =G12*(V12-(U12*W12)) -> 533.7612
A13: 12 | B13: AHMAD HILMI BIN KAMAL | C13: M | D13: 47 | E13: ENP | F13: 25 | G13: 80000 | H13: 20 | I13: None | J13: 0 | K13: 4 | L13: =IF(C13="F",D13-3,D13) -> 47 | M13: =(_xlfn.XLOOKUP(L13,'DGI TABLE'!$A$2:$A$91,'DGI TABLE'!$G$2:$G$91)-_xlfn.XLOOKUP(L13+F13,'DGI TABLE'!$A$2:$A$91,'DGI TABLE'!$G$2:$G$91)+_xlfn.XLOOKUP(L13+F13,'DGI TABLE'!$A$2:$A$91,'DGI TABLE'!$C$2:$C$91))/_xlfn.XLOOKUP(L13,'DGI TABLE'!$A$2:$A$91,'DGI TABLE'!$C$2:$C$91) -> 0.43406358 | N13: =(_xlfn.XLOOKUP(L13,'DGI TABLE'!$A$2:$A$91,'DGI TABLE'!$D$2:$D$91)-_xlfn.XLOOKUP(L13+H13,'DGI TABLE'!$A$2:$A$91,'DGI TABLE'!$D$2:$D$91))/_xlfn.XLOOKUP(L13,'DGI TABLE'!$A$2:$A$91,'DGI TABLE'!$C$2:$C$91) -> 13.16881 | O13: =M13/N13 -> 0.032961487 | P13: =(_xlfn.XLOOKUP(L13+1,'DGI TABLE'!$A$2:$A$91,'DGI TABLE'!$G$2:$G$91)-_xlfn.XLOOKUP(L13+F13,'DGI TABLE'!$A$2:$A$91,'DGI TABLE'!$G$2:$G$91))/_xlfn.XLOOKUP(L13+1,'DGI TABLE'!$A$2:$A$91,'DGI TABLE'!$C$2:$C$91) -> 0.19208633 | Q13: =(_xlfn.XLOOKUP(L13+1,'DGI TABLE'!$A$2:$A$91,'DGI TABLE'!$D$2:$D$91)-_xlfn.XLOOKUP(L13+H13,'DGI TABLE'!$A$2:$A$91,'DGI TABLE'!$D$2:$D$91))/_xlfn.XLOOKUP(L13+1,'DGI TABLE'!$A$2:$A$91,'DGI TABLE'!$C$2:$C$91) -> 12.719798 | R13: =_xlfn.XLOOKUP(L13,'DGI TABLE'!$A$2:$A$91,'DGI TABLE'!$F$2:$F$91)/_xlfn.XLOOKUP(L13,'DGI TABLE'!$A$2:$A$91,'DGI TABLE'!$C$2:$C$91) -> 0.0048557714 | S13: =P13/Q13 -> 0.015101367 | T13: =O13+0.03/N13 -> 0.035239597 | U13: =MIN(S13,T13) -> 0.015101367 | V13: =(_xlfn.XLOOKUP(L13+K13,'DGI TABLE'!$A$2:$A$91,'DGI TABLE'!$G$2:$G$91)-_xlfn.XLOOKUP(L13+F13,'DGI TABLE'!$A$2:$A$91,'DGI TABLE'!$G$2:$G$91))/_xlfn.XLOOKUP(L13+K13,'DGI TABLE'!$A$2:$A$91,'DGI TABLE'!$C$2:$C$91) -> 0.20096556 | W13: =(_xlfn.XLOOKUP(L13+K13,'DGI TABLE'!$A$2:$A$91,'DGI TABLE'!$D$2:$D$91)-_xlfn.XLOOKUP(L13+H13,'DGI TABLE'!$A$2:$A$91,'DGI TABLE'!$D$2:$D$91))/_xlfn.XLOOKUP(L13+K13,'DGI TABLE'!$A$2:$A$91,'DGI TABLE'!$C$2:$C$91) -> 11.283082 | X13: =G13*(V13-(U13*W13)) -> 2446.0486
A14: 13 | B14: MUHAMMAD ADIB BIN FAIZAL | C14: M | D14: 43 | E14: ENP | F14: 5 | G14: 60000 | H14: 4 | I14: None | J14: 0 | K14: 3 | L14: =IF(C14="F",D14-3,D14) -> 43 | M14: =(_xlfn.XLOOKUP(L14,'DGI TABLE'!$A$2:$A$91,'DGI TABLE'!$G$2:$G$91)-_xlfn.XLOOKUP(L14+F14,'DGI TABLE'!$A$2:$A$91,'DGI TABLE'!$G$2:$G$91)+_xlfn.XLOOKUP(L14+F14,'DGI TABLE'!$A$2:$A$91,'DGI TABLE'!$C$2:$C$91))/_xlfn.XLOOKUP(L14,'DGI TABLE'!$A$2:$A$91,'DGI TABLE'!$C$2:$C$91) -> 0.82323455 | N14: =(_xlfn.XLOOKUP(L14,'DGI TABLE'!$A$2:$A$91,'DGI TABLE'!$D$2:$D$91)-_xlfn.XLOOKUP(L14+H14,'DGI TABLE'!$A$2:$A$91,'DGI TABLE'!$D$2:$D$91))/_xlfn.XLOOKUP(L14,'DGI TABLE'!$A$2:$A$91,'DGI TABLE'!$C$2:$C$91) -> 3.7547867 | O14: =M14/N14 -> 0.21924935 | P14: =(_xlfn.XLOOKUP(L14+1,'DGI TABLE'!$A$2:$A$91,'DGI TABLE'!$G$2:$G$91)-_xlfn.XLOOKUP(L14+F14,'DGI TABLE'!$A$2:$A$91,'DGI TABLE'!$G$2:$G$91))/_xlfn.XLOOKUP(L14+1,'DGI TABLE'!$A$2:$A$91,'DGI TABLE'!$C$2:$C$91) -> 0.015860907 | Q14: =(_xlfn.XLOOKUP(L14+1,'DGI TABLE'!$A$2:$A$91,'DGI TABLE'!$D$2:$D$91)-_xlfn.XLOOKUP(L14+H14,'DGI TABLE'!$A$2:$A$91,'DGI TABLE'!$D$2:$D$91))/_xlfn.XLOOKUP(L14+1,'DGI TABLE'!$A$2:$A$91,'DGI TABLE'!$C$2:$C$91) -> 2.8750118 | R14: =_xlfn.XLOOKUP(L14,'DGI TABLE'!$A$2:$A$91,'DGI TABLE'!$F$2:$F$91)/_xlfn.XLOOKUP(L14,'DGI TABLE'!$A$2:$A$91,'DGI TABLE'!$C$2:$C$91) -> 0.0033557667 | S14: =P14/Q14 -> 0.0055168145 | T14: =O14+0.03/N14 -> 0.22723916 | U14: =MIN(S14,T14) -> 0.0055168145 | V14: =(_xlfn.XLOOKUP(L14+K14,'DGI TABLE'!$A$2:$A$91,'DGI TABLE'!$G$2:$G$91)-_xlfn.XLOOKUP(L14+F14,'DGI TABLE'!$A$2:$A$91,'DGI TABLE'!$G$2:$G$91))/_xlfn.XLOOKUP(L14+K14,'DGI TABLE'!$A$2:$A$91,'DGI TABLE'!$C$2:$C$91) -> 0.0090706087 | W14: =(_xlfn.XLOOKUP(L14+K14,'DGI TABLE'!$A$2:$A$91,'DGI TABLE'!$D$2:$D$91)-_xlfn.XLOOKUP(L14+H14,'DGI TABLE'!$A$2:$A$91,'DGI TABLE'!$D$2:$D$91))/_xlfn.XLOOKUP(L14+K14,'DGI TABLE'!$A$2:$A$91,'DGI TABLE'!$C$2:$C$91) -> 1 | X14: =G14*(V14-(U14*W14)) -> 213.22765
A15: 14 | B15: NUR FARAHIN BINTI OSMAN | C15: F | D15: 53 | E15: ENP | F15: 10 | G15: 175000 | H15: 3 | I15: None | J15: 0 | K15: 2 | L15: =IF(C15="F",D15-3,D15) -> 50 | M15: =(_xlfn.XLOOKUP(L15,'DGI TABLE'!$A$2:$A$91,'DGI TABLE'!$G$2:$G$91)-_xlfn.XLOOKUP(L15+F15,'DGI TABLE'!$A$2:$A$91,'DGI TABLE'!$G$2:$G$91)+_xlfn.XLOOKUP(L15+F15,'DGI TABLE'!$A$2:$A$91,'DGI TABLE'!$C$2:$C$91))/_xlfn.XLOOKUP(L15,'DGI TABLE'!$A$2:$A$91,'DGI TABLE'!$C$2:$C$91) -> 0.68675075 | N15: =(_xlfn.XLOOKUP(L15,'DGI TABLE'!$A$2:$A$91,'DGI TABLE'!$D$2:$D$91)-_xlfn.XLOOKUP(L15+H15,'DGI TABLE'!$A$2:$A$91,'DGI TABLE'!$D$2:$D$91))/_xlfn.XLOOKUP(L15,'DGI TABLE'!$A$2:$A$91,'DGI TABLE'!$C$2:$C$91) -> 2.8670245 | O15: =M15/N15 -> 0.23953432 | P15: =(_xlfn.XLOOKUP(L15+1,'DGI TABLE'!$A$2:$A$91,'DGI TABLE'!$G$2:$G$91)-_xlfn.XLOOKUP(L15+F15,'DGI TABLE'!$A$2:$A$91,'DGI TABLE'!$G$2:$G$91))/_xlfn.XLOOKUP(L15+1,'DGI TABLE'!$A$2:$A$91,'DGI TABLE'!$C$2:$C$91) -> 0.072866672 | Q15: =(_xlfn.XLOOKUP(L15+1,'DGI TABLE'!$A$2:$A$91,'DGI TABLE'!$D$2:$D$91)-_xlfn.XLOOKUP(L15+H15,'DGI TABLE'!$A$2:$A$91,'DGI TABLE'!$D$2:$D$91))/_xlfn.XLOOKUP(L15+1,'DGI TABLE'!$A$2:$A$91,'DGI TABLE'!$C$2:$C$91) -> 1.9546058 | R15: =_xlfn.XLOOKUP(L15,'DGI TABLE'!$A$2:$A$91,'DGI TABLE'!$F$2:$F$91)/_xlfn.XLOOKUP(L15,'DGI TABLE'!$A$2:$A$91,'DGI TABLE'!$C$2:$C$91) -> 0.0063461531 | S15: =P15/Q15 -> 0.037279471 | T15: =O15+0.03/N15 -> 0.24999813 | U15: =MIN(S15,T15) -> 0.037279471 | V15: =(_xlfn.XLOOKUP(L15+K15,'DGI TABLE'!$A$2:$A$91,'DGI TABLE'!$G$2:$G$91)-_xlfn.XLOOKUP(L15+F15,'DGI TABLE'!$A$2:$A$91,'DGI TABLE'!$G$2:$G$91))/_xlfn.XLOOKUP(L15+K15,'DGI TABLE'!$A$2:$A$91,'DGI TABLE'!$C$2:$C$91) -> 0.069069321 | W15: =(_xlfn.XLOOKUP(L15+K15,'DGI TABLE'!$A$2:$A$91,'DGI TABLE'!$D$2:$D$91)-_xlfn.XLOOKUP(L15+H15,'DGI TABLE'!$A$2:$A$91,'DGI TABLE'!$D$2:$D$91))/_xlfn.XLOOKUP(L15+K15,'DGI TABLE'!$A$2:$A$91,'DGI TABLE'!$C$2:$C$91) -> 0.99999991 | X15: =G15*(V15-(U15*W15)) -> 5563.2243
A16: 15 | B16: NUR HANNA BINTI AZMAN | C16: F | D16: 45 | E16: EPC | F16: 25 | G16: 75000 | H16: 20 | I16: CRB | J16: 0.05 | K16: 8 | L16: =IF(C16="F",D16-3,D16) -> 42 | M16: =(_xlfn.XLOOKUP(L16,'DGI TABLE'!$A$2:$A$91,'DGI TABLE'!$G$2:$G$91)-_xlfn.XLOOKUP(L16+F16,'DGI TABLE'!$A$2:$A$91,'DGI TABLE'!$G$2:$G$91)+_xlfn.XLOOKUP(L16+F16,'DGI TABLE'!$A$2:$A$91,'DGI TABLE'!$C$2:$C$91))/_xlfn.XLOOKUP(L16,'DGI TABLE'!$A$2:$A$91,'DGI TABLE'!$C$2:$C$91) -> 0.41479393 | N16: =(_xlfn.XLOOKUP(L16,'DGI TABLE'!$A$2:$A$91,'DGI TABLE'!$D$2:$D$91)-_xlfn.XLOOKUP(L16+H16,'DGI TABLE'!$A$2:$A$91,'DGI TABLE'!$D$2:$D$91))/_xlfn.XLOOKUP(L16,'DGI TABLE'!$A$2:$A$91,'DGI TABLE'!$C$2:$C$91) -> 13.492949 | O16: =M16/N16 -> 0.030741533 | P16: =(_xlfn.XLOOKUP(L16+1,'DGI TABLE'!$A$2:$A$91,'DGI TABLE'!$G$2:$G$91)-_xlfn.XLOOKUP(L16+F16,'DGI TABLE'!$A$2:$A$91,'DGI TABLE'!$G$2:$G$91))/_xlfn.XLOOKUP(L16+1,'DGI TABLE'!$A$2:$A$91,'DGI TABLE'!$C$2:$C$91) -> 0.13202441 | Q16: =(_xlfn.XLOOKUP(L16+1,'DGI TABLE'!$A$2:$A$91,'DGI TABLE'!$D$2:$D$91)-_xlfn.XLOOKUP(L16+H16,'DGI TABLE'!$A$2:$A$91,'DGI TABLE'!$D$2:$D$91))/_xlfn.XLOOKUP(L16+1,'DGI TABLE'!$A$2:$A$91,'DGI TABLE'!$C$2:$C$91) -> 13.034246 | R16: =_xlfn.XLOOKUP(L16,'DGI TABLE'!$A$2:$A$91,'DGI TABLE'!$F$2:$F$91)/_xlfn.XLOOKUP(L16,'DGI TABLE'!$A$2:$A$91,'DGI TABLE'!$C$2:$C$91) -> 0.0030673055 | S16: =P16/Q16 -> 0.010129041 | T16: =O16+0.03/N16 -> 0.032964917 | U16: =MIN(S16,T16) -> 0.010129041 | V16: =(_xlfn.XLOOKUP(L16+K16,'DGI TABLE'!$A$2:$A$91,'DGI TABLE'!$G$2:$G$91)-_xlfn.XLOOKUP(L16+F16,'DGI TABLE'!$A$2:$A$91,'DGI TABLE'!$G$2:$G$91))/_xlfn.XLOOKUP(L16+K16,'DGI TABLE'!$A$2:$A$91,'DGI TABLE'!$C$2:$C$91) -> 0.14242306 | W16: =(_xlfn.XLOOKUP(L16+K16,'DGI TABLE'!$A$2:$A$91,'DGI TABLE'!$D$2:$D$91)-_xlfn.XLOOKUP(L16+H16,'DGI TABLE'!$A$2:$A$91,'DGI TABLE'!$D$2:$D$91))/_xlfn.XLOOKUP(L16+K16,'DGI TABLE'!$A$2:$A$91,'DGI TABLE'!$C$2:$C$91) -> 9.3339091 | X16: =G16*((((1+J16)^(K16-1))*V16)-(U16*W16)) -> 7939.5
A17: 16 | B17: AHMAD LUQMAN BIN AZHAR | C17: M | D17: 49 | E17: EPC | F17: 15 | G17: 60000 | H17: 10 | I17: CRB | J17: 0.05 | K17: 4 | L17: =IF(C17="F",D17-3,D17) -> 49 | M17: =(_xlfn.XLOOKUP(L17,'DGI TABLE'!$A$2:$A$91,'DGI TABLE'!$G$2:$G$91)-_xlfn.XLOOKUP(L17+F17,'DGI TABLE'!$A$2:$A$91,'DGI TABLE'!$G$2:$G$91)+_xlfn.XLOOKUP(L17+F17,'DGI TABLE'!$A$2:$A$91,'DGI TABLE'!$C$2:$C$91))/_xlfn.XLOOKUP(L17,'DGI TABLE'!$A$2:$A$91,'DGI TABLE'!$C$2:$C$91) -> 0.5792917 | N17: =(_xlfn.XLOOKUP(L17,'DGI TABLE'!$A$2:$A$91,'DGI TABLE'!$D$2:$D$91)-_xlfn.XLOOKUP(L17+H17,'DGI TABLE'!$A$2:$A$91,'DGI TABLE'!$D$2:$D$91))/_xlfn.XLOOKUP(L17,'DGI TABLE'!$A$2:$A$91,'DGI TABLE'!$C$2:$C$91) -> 8.1683885 | O17: =M17/N17 -> 0.070918725 | P17: =(_xlfn.XLOOKUP(L17+1,'DGI TABLE'!$A$2:$A$91,'DGI TABLE'!$G$2:$G$91)-_xlfn.XLOOKUP(L17+F17,'DGI TABLE'!$A$2:$A$91,'DGI TABLE'!$G$2:$G$91))/_xlfn.XLOOKUP(L17+1,'DGI TABLE'!$A$2:$A$91,'DGI TABLE'!$C$2:$C$91) -> 0.11214937 | Q17: =(_xlfn.XLOOKUP(L17+1,'DGI TABLE'!$A$2:$A$91,'DGI TABLE'!$D$2:$D$91)-_xlfn.XLOOKUP(L17+H17,'DGI TABLE'!$A$2:$A$91,'DGI TABLE'!$D$2:$D$91))/_xlfn.XLOOKUP(L17+1,'DGI TABLE'!$A$2:$A$91,'DGI TABLE'!$C$2:$C$91) -> 7.5003516 | R17: =_xlfn.XLOOKUP(L17,'DGI TABLE'!$A$2:$A$91,'DGI TABLE'!$F$2:$F$91)/_xlfn.XLOOKUP(L17,'DGI TABLE'!$A$2:$A$91,'DGI TABLE'!$C$2:$C$91) -> 0.0057980762 | S17: =P17/Q17 -> 0.014952549 | T17: =O17+0.03/N17 -> 0.07459142 | U17: =MIN(S17,T17) -> 0.014952549 | V17: =(_xlfn.XLOOKUP(L17+K17,'DGI TABLE'!$A$2:$A$91,'DGI TABLE'!$G$2:$G$91)-_xlfn.XLOOKUP(L17+F17,'DGI TABLE'!$A$2:$A$91,'DGI TABLE'!$G$2:$G$91))/_xlfn.XLOOKUP(L17+K17,'DGI TABLE'!$A$2:$A$91,'DGI TABLE'!$C$2:$C$91) -> 0.10606003 | W17: =(_xlfn.XLOOKUP(L17+K17,'DGI TABLE'!$A$2:$A$91,'DGI TABLE'!$D$2:$D$91)-_xlfn.XLOOKUP(L17+H17,'DGI TABLE'!$A$2:$A$91,'DGI TABLE'!$D$2:$D$91))/_xlfn.XLOOKUP(L17+K17,'DGI TABLE'!$A$2:$A$91,'DGI TABLE'!$C$2:$C$91) -> 5.3266722 | X17: =G17*((((1+J17)^(K17-1))*V17)-(U17*W17)) -> 2587.8248
A18: 17 | B18: MUHAMMAD IKRAM BIN MUSTAFA | C18: M | D18: 59 | E18: EPC | F18: 10 | G18: 75000 | H18: 5 | I18: CRB | J18: 0.05 | K18: 8 | L18: =IF(C18="F",D18-3,D18) -> 59 | M18: =(_xlfn.XLOOKUP(L18,'DGI TABLE'!$A$2:$A$91,'DGI TABLE'!$G$2:$G$91)-_xlfn.XLOOKUP(L18+F18,'DGI TABLE'!$A$2:$A$91,'DGI TABLE'!$G$2:$G$91)+_xlfn.XLOOKUP(L18+F18,'DGI TABLE'!$A$2:$A$91,'DGI TABLE'!$C$2:$C$91))/_xlfn.XLOOKUP(L18,'DGI TABLE'!$A$2:$A$91,'DGI TABLE'!$C$2:$C$91) -> 0.69785898 | N18: =(_xlfn.XLOOKUP(L18,'DGI TABLE'!$A$2:$A$91,'DGI TABLE'!$D$2:$D$91)-_xlfn.XLOOKUP(L18+H18,'DGI TABLE'!$A$2:$A$91,'DGI TABLE'!$D$2:$D$91))/_xlfn.XLOOKUP(L18,'DGI TABLE'!$A$2:$A$91,'DGI TABLE'!$C$2:$C$91) -> 4.4995601 | O18: =M18/N18 -> 0.15509494 | P18: =(_xlfn.XLOOKUP(L18+1,'DGI TABLE'!$A$2:$A$91,'DGI TABLE'!$G$2:$G$91)-_xlfn.XLOOKUP(L18+F18,'DGI TABLE'!$A$2:$A$91,'DGI TABLE'!$G$2:$G$91))/_xlfn.XLOOKUP(L18+1,'DGI TABLE'!$A$2:$A$91,'DGI TABLE'!$C$2:$C$91) -> 0.1443595 | Q18: =(_xlfn.XLOOKUP(L18+1,'DGI TABLE'!$A$2:$A$91,'DGI TABLE'!$D$2:$D$91)-_xlfn.XLOOKUP(L18+H18,'DGI TABLE'!$A$2:$A$91,'DGI TABLE'!$D$2:$D$91))/_xlfn.XLOOKUP(L18+1,'DGI TABLE'!$A$2:$A$91,'DGI TABLE'!$C$2:$C$91) -> 3.6905082 | R18: =_xlfn.XLOOKUP(L18,'DGI TABLE'!$A$2:$A$91,'DGI TABLE'!$F$2:$F$91)/_xlfn.XLOOKUP(L18,'DGI TABLE'!$A$2:$A$91,'DGI TABLE'!$C$2:$C$91) -> 0.013278843 | S18: =P18/Q18 -> 0.039116429 | T18: =O18+0.03/N18 -> 0.16176225 | U18: =MIN(S18,T18) -> 0.039116429 | V18: =(_xlfn.XLOOKUP(L18+K18,'DGI TABLE'!$A$2:$A$91,'DGI TABLE'!$G$2:$G$91)-_xlfn.XLOOKUP(L18+F18,'DGI TABLE'!$A$2:$A$91,'DGI TABLE'!$G$2:$G$91))/_xlfn.XLOOKUP(L18+K18,'DGI TABLE'!$A$2:$A$91,'DGI TABLE'!$C$2:$C$91) -> 0.05363375 | W18: =(_xlfn.XLOOKUP(L18+K18,'DGI TABLE'!$A$2:$A$91,'DGI TABLE'!$D$2:$D$91)-_xlfn.XLOOKUP(L18+H18,'DGI TABLE'!$A$2:$A$91,'DGI TABLE'!$D$2:$D$91))/_xlfn.XLOOKUP(L18+K18,'DGI TABLE'!$A$2:$A$91,'DGI TABLE'!$C$2:$C$91) -> -3.4079893 | X18: =G18*((((1+J18)^(K18-1))*V18)-(U18*W18)) -> 15658.233
